Workbook

Sheet Sheet1
B1: feature_0001 | C1: feature_0002 | D1: feature_0003 | E1: feature_0004 | F1: feature_0005 | G1: feature_0006 | H1: feature_0007 | I1: feature_0008 | J1: feature_0009 | K1: feature_0010 | L1: feature_0011 | M1: feature_0012 | N1: feature_0013 | O1: feature_0014 | P1: feature_0015 | Q1: feature_0016 | R1: feature_0017 | S1: feature_0018 | T1: feature_0019 | U1: feature_0020 | V1: feature_0021 | W1: feature_0022 | X1: feature_0023 | Y1: feature_0024 | Z1: feature_0025 | AA1: feature_0026 | AB1: feature_0027 | AC1: feature_0028 | AD1: feature_0029 | AE1: feature_0030 | AF1: feature_0031 | AG1: feature_0032 | AH1: feature_0033 | AI1: feature_0034 | AJ1: feature_0035 | AK1: feature_0036 | AL1: feature_0037 | AM1: feature_0038 | AN1: feature_0039 | AO1: feature_0040 | AP1: feature_0041 | AQ1: feature_0042 | AR1: feature_0043 | AS1: feature_0044 | AT1: feature_0045 | AU1: feature_0046 | AV1: feature_0047 | AW1: feature_0048 | AX1: feature_0049 | AY1: feature_0050 | AZ1: feature_0051 | BA1: feature_0052 | BB1: feature_0053 | BC1: feature_0054 | BD1: feature_0055 | BE1: feature_0056 | BF1: feature_0057 | BG1: feature_0058 | BH1: feature_0059 | BI1: feature_0060 | BJ1: feature_0061 | BK1: feature_0062 | BL1: feature_0063 | BM1: feature_0064 | BN1: feature_0065 | BO1: feature_0066 | BP1: feature_0067 | BQ1: feature_0068 | BR1: feature_0069 | BS1: feature_0070 | BT1: feature_0071 | BU1: feature_0072 | BV1: feature_0073 | BW1: feature_0074 | BX1: feature_0075 | BY1: feature_0076 | BZ1: feature_0077 | CA1: feature_0078 | CB1: feature_0079 | CC1: feature_0080 | CD1: feature_0081 | CE1: feature_0082 | CF1: feature_0083 | CG1: feature_0084 | CH1: feature_0085 | CI1: feature_0086 | CJ1: feature_0087 | CK1: feature_0088 | CL1: feature_0089 | CM1: feature_0090 | CN1: feature_0091 | CO1: feature_0092 | CP1: feature_0093 | CQ1: feature_0094 | CR1: feature_0095 | CS1: feature_0096 | CT1: feature_0097 | CU1: feature_0098 | CV1: feature_0099 | CW1: feature_0100 | CX1: feature_0101 | CY1: feature_0102 | CZ1: feature_0103 | DA1: feature_0104 | DB1: feature_0105 | DC1: feature_0106 | DD1: feature_0107 | DE1: feature_0108 | DF1: feature_0109 | DG1: feature_0110 | DH1: feature_0111 | DI1: feature_0112 | DJ1: feature_0113 | DK1: feature_0114 | DL1: feature_0115 | DM1: feature_0116 | DN1: feature_0117 | DO1: feature_0118 | DP1: feature_0119 | DQ1: feature_0120 | DR1: feature_0121 | DS1: feature_0122 | DT1: feature_0123 | DU1: feature_0124 | DV1: feature_0125 | DW1: feature_0126 | DX1: feature_0127 | DY1: feature_0128 | DZ1: feature_0129 | EA1: feature_0130 | EB1: feature_0131 | EC1: feature_0132 | ED1: feature_0133 | EE1: feature_0134 | EF1: feature_0135 | EG1: feature_0136 | EH1: feature_0137 | EI1: feature_0138 | EJ1: feature_0139 | EK1: feature_0140 | EL1: feature_0141 | EM1: feature_0142 | EN1: feature_0143 | EO1: feature_0144 | EP1: feature_0145 | EQ1: feature_0146 | ER1: feature_0147 | ES1: feature_0148 | ET1: feature_0149 | EU1: feature_0150 | EV1: feature_0151 | EW1: feature_0152 | EX1: feature_0153 | EY1: feature_0154 | EZ1: feature_0155 | FA1: feature_0156 | FB1: feature_0157 | FC1: feature_0158 | FD1: feature_0159 | FE1: feature_0160 | FF1: feature_0161 | FG1: feature_0162 | FH1: feature_0163 | FI1: feature_0164 | FJ1: feature_0165 | FK1: feature_0166 | FL1: feature_0167 | FM1: feature_0168 | FN1: feature_0169 | FO1: feature_0170 | FP1: feature_0171 | FQ1: feature_0172 | FR1: feature_0173 | FS1: feature_0174 | FT1: feature_0175 | FU1: feature_0176 | FV1: feature_0177 | FW1: feature_0178 | FX1: feature_0179 | FY1: feature_0180 | FZ1: feature_0181 | GA1: feature_0182 | GB1: feature_0183 | GC1: feature_0184 | GD1: feature_0185 | GE1: feature_0186 | GF1: feature_0187 | GG1: feature_0188 | GH1: feature_0189 | GI1: feature_0190 | GJ1: feature_0191 | GK1: feature_0192 | GL1: feature_0193 | GM1: feature_0194 | GN1: feature_0195 | GO1: feature_0196 | GP1: feature_0197 | GQ1: feature_0198 | GR1: feature_0199 | GS1: feature_0200 | GT1: feature_0201 | GU1: feature_0202 | GV1: feature_0203 | GW1: feature_0204 | GX1: feature_0205 | GY1: feature_0206 | GZ1: feature_0207 | HA1: feature_0208 | HB1: feature_0209 | HC1: feature_0210 | HD1: feature_0211 | HE1: feature_0212 | HF1: feature_0213 | HG1: feature_0214 | HH1: feature_0215 | HI1: feature_0216 | HJ1: feature_0217 | HK1: feature_0218 | HL1: feature_0219 | HM1: feature_0220 | HN1: feature_0221 | HO1: feature_0222 | HP1: feature_0223 | HQ1: feature_0224 | HR1: feature_0225 | HS1: feature_0226 | HT1: feature_0227 | HU1: feature_0228 | HV1: feature_0229 | HW1: feature_0230 | HX1: feature_0231 | HY1: feature_0232 | HZ1: feature_0233 | IA1: feature_0234 | IB1: feature_0235 | IC1: feature_0236 | ID1: feature_0237 | IE1: feature_0238 | IF1: feature_0239 | IG1: feature_0240 | IH1: feature_0241 | II1: feature_0242 | IJ1: feature_0243 | IK1: feature_0244 | IL1: feature_0245 | IM1: feature_0246 | IN1: feature_0247 | IO1: feature_0248 | IP1: feature_0249 | IQ1: feature_0250 | IR1: feature_0251 | IS1: feature_0252 | IT1: feature_0253 | IU1: feature_0254 | IV1: feature_0255 | IW1: feature_0256 | IX1: feature_0257 | IY1: feature_0258 | IZ1: feature_0259 | JA1: feature_0260 | JB1: feature_0261 | JC1: feature_0262 | JD1: feature_0263 | JE1: feature_0264 | JF1: feature_0265 | JG1: feature_0266 | JH1: feature_0267 | JI1: feature_0268 | JJ1: feature_0269 | JK1: feature_0270 | JL1: feature_0271 | JM1: feature_0272 | JN1: feature_0273 | JO1: feature_0274 | JP1: feature_0275 | JQ1: feature_0276 | JR1: feature_0277 | JS1: feature_0278 | JT1: feature_0279 | JU1: feature_0280 | JV1: feature_0281 | JW1: feature_0282 | JX1: feature_0283 | JY1: feature_0284 | JZ1: feature_0285 | KA1: feature_0286 | KB1: feature_0287 | KC1: feature_0288 | KD1: feature_0289 | KE1: feature_0290 | KF1: feature_0291 | KG1: feature_0292 | KH1: feature_0293 | KI1: feature_0294 | KJ1: feature_0295 | KK1: feature_0296 | KL1: feature_0297 | KM1: feature_0298 | KN1: feature_0299 | KO1: feature_0300 | KP1: feature_0301 | KQ1: feature_0302 | KR1: feature_0303 | KS1: feature_0304 | KT1: feature_0305 | KU1: feature_0306 | KV1: feature_0307 | KW1: feature_0308 | KX1: feature_0309 | KY1: feature_0310 | KZ1: feature_0311 | LA1: feature_0312 | LB1: feature_0313 | LC1: feature_0314 | LD1: feature_0315 | LE1: feature_0316 | LF1: feature_0317 | LG1: feature_0318 | LH1: feature_0319 | LI1: feature_0320 | LJ1: feature_0321 | LK1: feature_0322 | LL1: feature_0323 | LM1: feature_0324 | LN1: feature_0325 | LO1: feature_0326 | LP1: feature_0327 | LQ1: feature_0328 | LR1: feature_0329 | LS1: feature_0330 | LT1: feature_0331 | LU1: feature_0332 | LV1: feature_0333 | LW1: feature_0334 | LX1: feature_0335 | LY1: feature_0336 | LZ1: feature_0337 | MA1: feature_0338 | MB1: feature_0339 | MC1: feature_0340 | MD1: feature_0341 | ME1: feature_0342 | MF1: feature_0343 | MG1: feature_0344 | MH1: feature_0345 | MI1: feature_0346 | MJ1: feature_0347 | MK1: feature_0348 | ML1: feature_0349 | MM1: feature_0350 | MN1: feature_0351 | MO1: feature_0352 | MP1: feature_0353 | MQ1: feature_0354 | MR1: feature_0355 | MS1: feature_0356 | MT1: feature_0357 | MU1: feature_0358 | MV1: feature_0359 | MW1: feature_0360 | MX1: feature_0361 | MY1: feature_0362 | MZ1: feature_0363 | NA1: feature_0364 | NB1: feature_0365 | NC1: feature_0366 | ND1: feature_0367 | NE1: feature_0368 | NF1: feature_0369 | NG1: feature_0370 | NH1: feature_0371 | NI1: feature_0372 | NJ1: feature_0373 | NK1: feature_0374 | NL1: feature_0375 | NM1: feature_0376 | NN1: feature_0377 | NO1: feature_0378 | NP1: feature_0379 | NQ1: feature_0380 | NR1: feature_0381 | NS1: feature_0382 | NT1: feature_0383 | NU1: feature_0384 | NV1: feature_0385 | NW1: feature_0386 | NX1: feature_0387 | NY1: feature_0388 | NZ1: feature_0389 | OA1: feature_0390 | OB1: feature_0391 | OC1: feature_0392 | OD1: feature_0393 | OE1: feature_0394 | OF1: feature_0395 | OG1: feature_0396 | OH1: feature_0397 | OI1: feature_0398 | OJ1: feature_0399 | OK1: feature_0400 | OL1: feature_0401 | OM1: feature_0402 | ON1: feature_0403 | OO1: feature_0404 | OP1: feature_0405 | OQ1: feature_0406 | OR1: feature_0407 | OS1: feature_0408 | OT1: feature_0409 | OU1: feature_0410 | OV1: feature_0411 | OW1: feature_0412 | OX1: feature_0413 | OY1: feature_0414 | OZ1: feature_0415 | PA1: feature_0416 | PB1: feature_0417 | PC1: feature_0418 | PD1: feature_0419 | PE1: feature_0420 | PF1: feature_0421 | PG1: feature_0422 | PH1: feature_0423 | PI1: feature_0424 | PJ1: feature_0425 | PK1: feature_0426 | PL1: feature_0427 | PM1: feature_0428 | PN1: feature_0429 | PO1: feature_0430 | PP1: feature_0431 | PQ1: feature_0432 | PR1: feature_0433 | PS1: feature_0434 | PT1: feature_0435 | PU1: feature_0436 | PV1: feature_0437 | PW1: feature_0438 | PX1: feature_0439 | PY1: feature_0440 | PZ1: feature_0441 | QA1: feature_0442 | QB1: feature_0443 | QC1: feature_0444 | QD1: feature_0445 | QE1: feature_0446 | QF1: feature_0447 | QG1: feature_0448 | QH1: feature_0449 | QI1: feature_0450 | QJ1: feature_0451 | QK1: feature_0452 | QL1: feature_0453 | QM1: feature_0454 | QN1: feature_0455 | QO1: feature_0456 | QP1: feature_0457 | QQ1: feature_0458 | QR1: feature_0459 | QS1: feature_0460 | QT1: feature_0461 | QU1: feature_0462 | QV1: feature_0463 | QW1: feature_0464 | QX1: feature_0465 | QY1: feature_0466 | QZ1: feature_0467 | RA1: feature_0468 | RB1: feature_0469 | RC1: feature_0470 | RD1: feature_0471 | RE1: feature_0472 | RF1: feature_0473 | RG1: feature_0474 | RH1: feature_0475 | RI1: feature_0476 | RJ1: feature_0477 | RK1: feature_0478 | RL1: feature_0479 | RM1: feature_0480 | RN1: feature_0481 | RO1: feature_0482 | RP1: feature_0483 | RQ1: feature_0484 | RR1: feature_0485 | RS1: feature_0486 | RT1: feature_0487 | RU1: feature_0488 | RV1: feature_0489 | RW1: feature_0490 | RX1: feature_0491 | RY1: feature_0492 | RZ1: feature_0493 | SA1: feature_0494 | SB1: feature_0495 | SC1: feature_0496 | SD1: feature_0497 | SE1: feature_0498 | SF1: feature_0499 | SG1: feature_0500 | SH1: feature_0501 | SI1: feature_0502 | SJ1: feature_0503 | SK1: feature_0504 | SL1: feature_0505 | SM1: feature_0506 | SN1: feature_0507 | SO1: feature_0508 | SP1: feature_0509 | SQ1: feature_0510 | SR1: feature_0511 | SS1: feature_0512 | ST1: feature_0513 | SU1: feature_0514 | SV1: feature_0515 | SW1: feature_0516 | SX1: feature_0517 | SY1: feature_0518 | SZ1: feature_0519 | TA1: feature_0520 | TB1: feature_0521 | TC1: feature_0522 | TD1: feature_0523 | TE1: feature_0524 | TF1: feature_0525 | TG1: feature_0526 | TH1: feature_0527 | TI1: feature_0528 | TJ1: feature_0529 | TK1: feature_0530 | TL1: feature_0531 | TM1: feature_0532 | TN1: feature_0533 | TO1: feature_0534 | TP1: feature_0535 | TQ1: feature_0536 | TR1: feature_0537 | TS1: feature_0538 | TT1: feature_0539 | TU1: feature_0540 | TV1: feature_0541 | TW1: feature_0542 | TX1: feature_0543 | TY1: feature_0544 | TZ1: feature_0545 | UA1: feature_0546 | UB1: feature_0547 | UC1: feature_0548 | UD1: feature_0549 | UE1: feature_0550 | UF1: feature_0551 | UG1: feature_0552 | UH1: feature_0553 | UI1: feature_0554 | UJ1: feature_0555 | UK1: feature_0556 | UL1: feature_0557 | UM1: feature_0558 | UN1: feature_0559 | UO1: feature_0560 | UP1: feature_0561 | UQ1: feature_0562 | UR1: feature_0563 | US1: feature_0564 | UT1: feature_0565 | UU1: feature_0566 | UV1: feature_0567 | UW1: feature_0568 | UX1: feature_0569 | UY1: feature_0570 | UZ1: feature_0571 | VA1: feature_0572 | VB1: feature_0573 | VC1: feature_0574 | VD1: feature_0575 | VE1: feature_0576 | VF1: feature_0577 | VG1: feature_0578 | VH1: feature_0579 | VI1: feature_0580 | VJ1: feature_0581 | VK1: feature_0582 | VL1: feature_0583 | VM1: feature_0584 | VN1: feature_0585 | VO1: feature_0586 | VP1: feature_0587 | VQ1: feature_0588 | VR1: feature_0589 | VS1: feature_0590 | VT1: feature_0591 | VU1: feature_0592 | VV1: feature_0593 | VW1: feature_0594 | VX1: feature_0595 | VY1: feature_0596 | VZ1: feature_0597 | WA1: feature_0598 | WB1: feature_0599 | WC1: feature_0600 | WD1: feature_0601 | WE1: feature_0602 | WF1: feature_0603 | WG1: feature_0604 | WH1: feature_0605 | WI1: feature_0606 | WJ1: feature_0607 | WK1: feature_0608 | WL1: feature_0609 | WM1: feature_0610 | WN1: feature_0611 | WO1: feature_0612 | WP1: feature_0613 | WQ1: feature_0614 | WR1: feature_0615 | WS1: feature_0616 | WT1: feature_0617 | WU1: feature_0618 | WV1: feature_0619 | WW1: feature_0620 | WX1: feature_0621 | WY1: feature_0622 | WZ1: feature_0623 | XA1: feature_0624 | XB1: feature_0625 | XC1: feature_0626 | XD1: feature_0627 | XE1: feature_0628 | XF1: feature_0629 | XG1: feature_0630 | XH1: feature_0631 | XI1: feature_0632 | XJ1: feature_0633 | XK1: feature_0634 | XL1: feature_0635 | XM1: feature_0636 | XN1: feature_0637 | XO1: feature_0638 | XP1: feature_0639 | XQ1: feature_0640 | XR1: feature_0641 | XS1: feature_0642 | XT1: feature_0643 | XU1: feature_0644 | XV1: feature_0645 | XW1: feature_0646 | XX1: feature_0647 | XY1: feature_0648 | XZ1: feature_0649 | YA1: feature_0650 | YB1: feature_0651 | YC1: feature_0652 | YD1: feature_0653 | YE1: feature_0654 | YF1: feature_0655 | YG1: feature_0656 | YH1: feature_0657 | YI1: feature_0658 | YJ1: feature_0659 | YK1: feature_0660 | YL1: feature_0661 | YM1: feature_0662 | YN1: feature_0663 | YO1: feature_0664 | YP1: feature_0665 | YQ1: feature_0666 | YR1: feature_0667 | YS1: feature_0668 | YT1: feature_0669 | YU1: feature_0670 | YV1: feature_0671 | YW1: feature_0672 | YX1: feature_0673 | YY1: feature_0674 | YZ1: feature_0675 | ZA1: feature_0676 | ZB1: feature_0677 | ZC1: feature_0678 | ZD1: feature_0679 | ZE1: feature_0680 | ZF1: feature_0681 | ZG1: feature_0682 | ZH1: feature_0683 | ZI1: feature_0684 | ZJ1: feature_0685 | ZK1: feature_0686 | ZL1: feature_0687 | ZM1: feature_0688 | ZN1: feature_0689 | ZO1: feature_0690 | ZP1: feature_0691 | ZQ1: feature_0692 | ZR1: feature_0693 | ZS1: feature_0694 | ZT1: feature_0695 | ZU1: feature_0696 | ZV1: feature_0697 | ZW1: feature_0698 | ZX1: feature_0699 | ZY1: feature_0700 | ZZ1: feature_0701 | AAA1: feature_0702 | AAB1: feature_0703 | AAC1: feature_0704 | AAD1: feature_0705 | AAE1: feature_0706 | AAF1: feature_0707 | AAG1: feature_0708 | AAH1: feature_0709 | AAI1: feature_0710 | AAJ1: feature_0711 | AAK1: feature_0712 | AAL1: feature_0713 | AAM1: feature_0714 | AAN1: feature_0715 | AAO1: feature_0716 | AAP1: feature_0717 | AAQ1: feature_0718 | AAR1: feature_0719 | AAS1: feature_0720 | AAT1: feature_0721 | AAU1: feature_0722 | AAV1: feature_0723 | AAW1: feature_0724 | AAX1: feature_0725 | AAY1: feature_0726 | AAZ1: feature_0727 | ABA1: feature_0728 | ABB1: feature_0729 | ABC1: feature_0730 | ABD1: feature_0731 | ABE1: feature_0732 | ABF1: feature_0733 | ABG1: feature_0734 | ABH1: feature_0735 | ABI1: feature_0736 | ABJ1: feature_0737 | ABK1: feature_0738 | ABL1: feature_0739 | ABM1: feature_0740 | ABN1: feature_0741 | ABO1: feature_0742 | ABP1: feature_0743 | ABQ1: feature_0744 | ABR1: feature_0745 | ABS1: feature_0746 | ABT1: feature_0747 | ABU1: feature_0748 | ABV1: feature_0749 | ABW1: feature_0750 | ABX1: feature_0751 | ABY1: feature_0752 | ABZ1: feature_0753 | ACA1: feature_0754 | ACB1: feature_0755 | ACC1: feature_0756 | ACD1: feature_0757 | ACE1: feature_0758 | ACF1: feature_0759 | ACG1: feature_0760 | ACH1: feature_0761 | ACI1: feature_0762 | ACJ1: feature_0763 | ACK1: feature_0764 | ACL1: feature_0765 | ACM1: feature_0766 | ACN1: feature_0767 | ACO1: feature_0768 | ACP1: feature_0769 | ACQ1: feature_0770 | ACR1: feature_0771 | ACS1: feature_0772 | ACT1: feature_0773 | ACU1: feature_0774 | ACV1: feature_0775 | ACW1: feature_0776 | ACX1: feature_0777 | ACY1: feature_0778 | ACZ1: feature_0779 | ADA1: feature_0780 | ADB1: feature_0781 | ADC1: feature_0782 | ADD1: feature_0783 | ADE1: feature_0784 | ADF1: feature_0785 | ADG1: feature_0786 | ADH1: feature_0787 | ADI1: feature_0788 | ADJ1: feature_0789 | ADK1: feature_0790 | ADL1: feature_0791 | ADM1: feature_0792 | ADN1: feature_0793 | ADO1: feature_0794 | ADP1: feature_0795 | ADQ1: feature_0796 | ADR1: feature_0797 | ADS1: feature_0798 | ADT1: feature_0799 | ADU1: feature_0800 | ADV1: feature_0801 | ADW1: feature_0802 | ADX1: feature_0803 | ADY1: feature_0804 | ADZ1: feature_0805 | AEA1: feature_0806 | AEB1: feature_0807 | AEC1: feature_0808 | AED1: feature_0809 | AEE1: feature_0810 | AEF1: feature_0811 | AEG1: feature_0812 | AEH1: feature_0813 | AEI1: feature_0814 | AEJ1: feature_0815 | AEK1: feature_0816 | AEL1: feature_0817 | AEM1: feature_0818 | AEN1: feature_0819 | AEO1: feature_0820 | AEP1: feature_0821 | AEQ1: feature_0822 | AER1: feature_0823 | AES1: feature_0824 | AET1: feature_0825 | AEU1: feature_0826 | AEV1: feature_0827 | AEW1: feature_0828 | AEX1: feature_0829 | AEY1: feature_0830 | AEZ1: feature_0831 | AFA1: feature_0832 | AFB1: feature_0833 | AFC1: feature_0834 | AFD1: feature_0835 | AFE1: feature_0836 | AFF1: feature_0837 | AFG1: feature_0838 | AFH1: feature_0839 | AFI1: feature_0840 | AFJ1: feature_0841 | AFK1: feature_0842 | AFL1: feature_0843 | AFM1: feature_0844 | AFN1: feature_0845 | AFO1: feature_0846 | AFP1: feature_0847 | AFQ1: feature_0848 | AFR1: feature_0849 | AFS1: feature_0850 | AFT1: feature_0851 | AFU1: feature_0852 | AFV1: feature_0853 | AFW1: feature_0854 | AFX1: feature_0855 | AFY1: feature_0856 | AFZ1: feature_0857 | AGA1: feature_0858 | AGB1: feature_0859 | AGC1: feature_0860 | AGD1: feature_0861 | AGE1: feature_0862 | AGF1: feature_0863 | AGG1: feature_0864 | AGH1: feature_0865 | AGI1: feature_0866 | AGJ1: feature_0867 | AGK1: feature_0868 | AGL1: feature_0869 | AGM1: feature_0870 | AGN1: feature_0871 | AGO1: feature_0872 | AGP1: feature_0873 | AGQ1: feature_0874 | AGR1: feature_0875 | AGS1: feature_0876 | AGT1: feature_0877 | AGU1: feature_0878 | AGV1: feature_0879 | AGW1: feature_0880 | AGX1: feature_0881 | AGY1: feature_0882 | AGZ1: feature_0883 | AHA1: feature_0884 | AHB1: feature_0885 | AHC1: feature_0886 | AHD1: feature_0887 | AHE1: feature_0888 | AHF1: feature_0889 | AHG1: feature_0890 | AHH1: feature_0891 | AHI1: feature_0892 | AHJ1: feature_0893 | AHK1: feature_0894 | AHL1: feature_0895 | AHM1: feature_0896 | AHN1: feature_0897 | AHO1: feature_0898 | AHP1: feature_0899 | AHQ1: feature_0900 | AHR1: feature_0901 | AHS1: feature_0902 | AHT1: feature_0903 | AHU1: feature_0904 | AHV1: feature_0905 | AHW1: feature_0906 | AHX1: feature_0907 | AHY1: feature_0908 | AHZ1: feature_0909 | AIA1: feature_0910 | AIB1: feature_0911 | AIC1: feature_0912 | AID1: feature_0913 | AIE1: feature_0914 | AIF1: feature_0915 | AIG1: feature_0916 | AIH1: feature_0917 | AII1: feature_0918 | AIJ1: feature_0919 | AIK1: feature_0920 | AIL1: feature_0921 | AIM1: feature_0922 | AIN1: feature_0923 | AIO1: feature_0924 | AIP1: feature_0925 | AIQ1: feature_0926 | AIR1: feature_0927 | AIS1: feature_0928 | AIT1: feature_0929 | AIU1: feature_0930 | AIV1: feature_0931 | AIW1: feature_0932 | AIX1: feature_0933 | AIY1: feature_0934 | AIZ1: feature_0935 | AJA1: feature_0936 | AJB1: feature_0937 | AJC1: feature_0938 | AJD1: feature_0939 | AJE1: feature_0940 | AJF1: feature_0941 | AJG1: feature_0942 | AJH1: feature_0943 | AJI1: feature_0944 | AJJ1: feature_0945 | AJK1: feature_0946 | AJL1: feature_0947 | AJM1: feature_0948 | AJN1: feature_0949 | AJO1: feature_0950 | AJP1: feature_0951 | AJQ1: feature_0952 | AJR1: feature_0953 | AJS1: feature_0954 | AJT1: feature_0955 | AJU1: feature_0956 | AJV1: feature_0957 | AJW1: feature_0958 | AJX1: feature_0959 | AJY1: feature_0960 | AJZ1: feature_0961 | AKA1: feature_0962 | AKB1: feature_0963 | AKC1: feature_0964 | AKD1: feature_0965 | AKE1: feature_0966 | AKF1: feature_0967 | AKG1: feature_0968 | AKH1: feature_0969 | AKI1: feature_0970 | AKJ1: feature_0971 | AKK1: feature_0972 | AKL1: feature_0973 | AKM1: feature_0974 | AKN1: feature_0975 | AKO1: feature_0976 | AKP1: feature_0977 | AKQ1: feature_0978 | AKR1: feature_0979 | AKS1: feature_0980 | AKT1: feature_0981 | AKU1: feature_0982 | AKV1: feature_0983 | AKW1: feature_0984 | AKX1: feature_0985 | AKY1: feature_0986 | AKZ1: feature_0987 | ALA1: feature_0988 | ALB1: feature_0989 | ALC1: feature_0990 | ALD1: feature_0991 | ALE1: feature_0992 | ALF1: feature_0993 | ALG1: feature_0994 | ALH1: feature_0995 | ALI1: feature_0996 | ALJ1: feature_0997 | ALK1: feature_0998 | ALL1: feature_0999 | ALM1: feature_1000 | ALN1: feature_1001 | ALO1: feature_1002 | ALP1: feature_1003 | ALQ1: feature_1004 | ALR1: feature_1005 | ALS1: feature_1006 | ALT1: feature_1007 | ALU1: feature_1008 | ALV1: feature_1009 | ALW1: feature_1010 | ALX1: feature_1011 | ALY1: feature_1012 | ALZ1: feature_1013 | AMA1: feature_1014 | AMB1: feature_1015 | AMC1: feature_1016 | AMD1: feature_1017 | AME1: feature_1018 | AMF1: feature_1019 | AMG1: feature_1020 | AMH1: feature_1021 | AMI1: feature_1022 | AMJ1: feature_1023 | AMK1: feature_1024 | AML1: feature_1025 | AMM1: feature_1026 | AMN1: feature_1027 | AMO1: feature_1028 | AMP1: feature_1029 | AMQ1: feature_1030 | AMR1: feature_1031 | AMS1: feature_1032 | AMT1: feature_1033 | AMU1: feature_1034 | AMV1: feature_1035 | AMW1: feature_1036 | AMX1: feature_1037 | AMY1: feature_1038 | AMZ1: feature_1039 | ANA1: feature_1040 | ANB1: feature_1041 | ANC1: feature_1042 | AND1: feature_1043 | ANE1: feature_1044 | ANF1: feature_1045 | ANG1: feature_1046 | ANH1: feature_1047 | ANI1: feature_1048 | ANJ1: feature_1049 | ANK1: feature_1050 | ANL1: feature_1051 | ANM1: feature_1052 | ANN1: feature_1053 | ANO1: feature_1054 | ANP1: feature_1055 | ANQ1: feature_1056 | ANR1: feature_1057 | ANS1: feature_1058 | ANT1: feature_1059 | ANU1: feature_1060 | ANV1: feature_1061 | ANW1: feature_1062 | ANX1: feature_1063 | ANY1: feature_1064 | ANZ1: feature_1065 | AOA1: feature_1066 | AOB1: feature_1067 | AOC1: feature_1068 | AOD1: feature_1069 | AOE1: feature_1070 | AOF1: feature_1071 | AOG1: feature_1072 | AOH1: feature_1073 | AOI1: feature_1074 | AOJ1: feature_1075 | AOK1: feature_1076 | AOL1: feature_1077 | AOM1: feature_1078 | AON1: feature_1079 | AOO1: feature_1080 | AOP1: feature_1081 | AOQ1: feature_1082 | AOR1: feature_1083 | AOS1: feature_1084 | AOT1: feature_1085 | AOU1: feature_1086 | AOV1: feature_1087 | AOW1: feature_1088 | AOX1: feature_1089 | AOY1: feature_1090 | AOZ1: feature_1091 | APA1: feature_1092 | APB1: feature_1093 | APC1: feature_1094 | APD1: feature_1095 | APE1: feature_1096 | APF1: feature_1097 | APG1: feature_1098 | APH1: feature_1099 | API1: feature_1100 | APJ1: feature_1101 | APK1: feature_1102 | APL1: feature_1103 | APM1: feature_1104 | APN1: feature_1105 | APO1: feature_1106 | APP1: feature_1107 | APQ1: feature_1108 | APR1: feature_1109 | APS1: feature_1110 | APT1: feature_1111 | APU1: feature_1112 | APV1: feature_1113 | APW1: feature_1114 | APX1: feature_1115 | APY1: feature_1116 | APZ1: feature_1117 | AQA1: feature_1118 | AQB1: feature_1119 | AQC1: feature_1120 | AQD1: feature_1121 | AQE1: feature_1122 | AQF1: feature_1123 | AQG1: feature_1124 | AQH1: feature_1125 | AQI1: feature_1126 | AQJ1: feature_1127 | AQK1: feature_1128 | AQL1: feature_1129 | AQM1: feature_1130 | AQN1: feature_1131 | AQO1: feature_1132 | AQP1: feature_1133 | AQQ1: feature_1134 | AQR1: feature_1135 | AQS1: feature_1136 | AQT1: feature_1137 | AQU1: feature_1138 | AQV1: feature_1139 | AQW1: feature_1140 | AQX1: feature_1141 | AQY1: feature_1142 | AQZ1: feature_1143 | ARA1: feature_1144 | ARB1: feature_1145 | ARC1: feature_1146 | ARD1: feature_1147 | ARE1: feature_1148 | ARF1: feature_1149 | ARG1: feature_1150 | ARH1: feature_1151 | ARI1: feature_1152 | ARJ1: feature_1153 | ARK1: feature_1154 | ARL1: feature_1155 | ARM1: feature_1156 | ARN1: feature_1157 | ARO1: feature_1158 | ARP1: feature_1159 | ARQ1: feature_1160 | ARR1: feature_1161 | ARS1: feature_1162 | ART1: feature_1163 | ARU1: feature_1164 | ARV1: feature_1165 | ARW1: feature_1166 | ARX1: feature_1167 | ARY1: feature_1168 | ARZ1: feature_1169 | ASA1: feature_1170 | ASB1: feature_1171 | ASC1: feature_1172 | ASD1: feature_1173 | ASE1: feature_1174 | ASF1: feature_1175 | ASG1: feature_1176 | ASH1: feature_1177 | ASI1: feature_1178 | ASJ1: feature_1179 | ASK1: feature_1180 | ASL1: feature_1181 | ASM1: feature_1182 | ASN1: feature_1183 | ASO1: feature_1184 | ASP1: feature_1185 | ASQ1: feature_1186 | ASR1: feature_1187 | ASS1: feature_1188 | AST1: feature_1189 | ASU1: feature_1190 | ASV1: feature_1191 | ASW1: feature_1192 | ASX1: feature_1193 | ASY1: feature_1194 | ASZ1: feature_1195 | ATA1: feature_1196 | ATB1: feature_1197 | ATC1: feature_1198 | ATD1: feature_1199 | ATE1: feature_1200 | ATF1: feature_1201 | ATG1: feature_1202 | ATH1: feature_1203 | ATI1: feature_1204 | ATJ1: feature_1205 | ATK1: feature_1206 | ATL1: feature_1207 | ATM1: feature_1208 | ATN1: feature_1209 | ATO1: feature_1210 | ATP1: feature_1211 | ATQ1: feature_1212 | ATR1: feature_1213 | ATS1: feature_1214 | ATT1: feature_1215 | ATU1: feature_1216 | ATV1: feature_1217 | ATW1: feature_1218 | ATX1: feature_1219 | ATY1: feature_1220 | ATZ1: feature_1221 | AUA1: feature_1222 | AUB1: feature_1223 | AUC1: feature_1224 | AUD1: feature_1225 | AUE1: feature_1226 | AUF1: feature_1227 | AUG1: feature_1228 | AUH1: feature_1229 | AUI1: feature_1230 | AUJ1: feature_1231 | AUK1: feature_1232 | AUL1: feature_1233 | AUM1: feature_1234 | AUN1: feature_1235 | AUO1: feature_1236 | AUP1: feature_1237 | AUQ1: feature_1238 | AUR1: feature_1239 | AUS1: feature_1240 | AUT1: feature_1241 | AUU1: feature_1242 | AUV1: feature_1243 | AUW1: feature_1244 | AUX1: feature_1245 | AUY1: feature_1246 | AUZ1: feature_1247 | AVA1: feature_1248 | AVB1: feature_1249 | AVC1: feature_1250 | AVD1: feature_1251 | AVE1: feature_1252 | AVF1: feature_1253 | AVG1: feature_1254 | AVH1: feature_1255 | AVI1: feature_1256 | AVJ1: feature_1257 | AVK1: feature_1258 | AVL1: feature_1259 | AVM1: feature_1260 | AVN1: feature_1261 | AVO1: feature_1262 | AVP1: feature_1263 | AVQ1: feature_1264 | AVR1: feature_1265 | AVS1: feature_1266 | AVT1: feature_1267 | AVU1: feature_1268 | AVV1: feature_1269 | AVW1: feature_1270 | AVX1: feature_1271 | AVY1: feature_1272 | AVZ1: feature_1273 | AWA1: feature_1274 | AWB1: feature_1275 | AWC1: feature_1276 | AWD1: feature_1277 | AWE1: feature_1278 | AWF1: feature_1279 | AWG1: feature_1280 | AWH1: feature_1281 | AWI1: feature_1282 | AWJ1: feature_1283 | AWK1: feature_1284 | AWL1: feature_1285 | AWM1: feature_1286 | AWN1: feature_1287 | AWO1: feature_1288 | AWP1: feature_1289 | AWQ1: feature_1290 | AWR1: feature_1291 | AWS1: feature_1292 | AWT1: feature_1293 | AWU1: feature_1294 | AWV1: feature_1295 | AWW1: feature_1296 | AWX1: feature_1297 | AWY1: feature_1298 | AWZ1: feature_1299 | AXA1: feature_1300 | AXB1: feature_1301 | AXC1: feature_1302 | AXD1: feature_1303 | AXE1: feature_1304 | AXF1: feature_1305 | AXG1: feature_1306 | AXH1: feature_1307 | AXI1: feature_1308 | AXJ1: feature_1309 | AXK1: feature_1310 | AXL1: feature_1311 | AXM1: feature_1312 | AXN1: feature_1313 | AXO1: feature_1314 | AXP1: feature_1315 | AXQ1: feature_1316 | AXR1: feature_1317 | AXS1: feature_1318 | AXT1: feature_1319 | AXU1: feature_1320 | AXV1: feature_1321 | AXW1: feature_1322 | AXX1: feature_1323 | AXY1: feature_1324 | AXZ1: feature_1325 | AYA1: feature_1326 | AYB1: feature_1327 | AYC1: feature_1328 | AYD1: feature_1329 | AYE1: feature_1330 | AYF1: feature_1331 | AYG1: feature_1332 | AYH1: feature_1333 | AYI1: feature_1334 | AYJ1: feature_1335 | AYK1: feature_1336 | AYL1: feature_1337 | AYM1: feature_1338 | AYN1: feature_1339 | AYO1: feature_1340 | AYP1: feature_1341 | AYQ1: feature_1342 | AYR1: feature_1343 | AYS1: feature_1344 | AYT1: feature_1345 | AYU1: feature_1346 | AYV1: feature_1347 | AYW1: feature_1348 | AYX1: feature_1349 | AYY1: feature_1350 | AYZ1: feature_1351 | AZA1: feature_1352 | AZB1: feature_1353 | AZC1: feature_1354 | AZD1: feature_1355 | AZE1: feature_1356 | AZF1: feature_1357 | AZG1: feature_1358 | AZH1: feature_1359 | AZI1: feature_1360 | AZJ1: feature_1361 | AZK1: feature_1362 | AZL1: feature_1363 | AZM1: feature_1364 | AZN1: feature_1365 | AZO1: feature_1366 | AZP1: feature_1367 | AZQ1: feature_1368 | AZR1: feature_1369 | AZS1: feature_1370 | AZT1: feature_1371 | AZU1: feature_1372 | AZV1: feature_1373 | AZW1: feature_1374 | AZX1: feature_1375 | AZY1: feature_1376 | AZZ1: feature_1377 | BAA1: feature_1378 | BAB1: feature_1379 | BAC1: feature_1380 | BAD1: feature_1381 | BAE1: feature_1382 | BAF1: feature_1383 | BAG1: feature_1384 | BAH1: feature_1385 | BAI1: feature_1386 | BAJ1: feature_1387 | BAK1: feature_1388 | BAL1: feature_1389 | BAM1: feature_1390 | BAN1: feature_1391 | BAO1: feature_1392 | BAP1: feature_1393 | BAQ1: feature_1394 | BAR1: feature_1395 | BAS1: feature_1396 | BAT1: feature_1397 | BAU1: feature_1398 | BAV1: feature_1399 | BAW1: feature_1400 | BAX1: feature_1401 | BAY1: feature_1402 | BAZ1: feature_1403 | BBA1: feature_1404 | BBB1: feature_1405 | BBC1: feature_1406 | BBD1: feature_1407 | BBE1: feature_1408 | BBF1: feature_1409 | BBG1: feature_1410 | BBH1: feature_1411 | BBI1: feature_1412 | BBJ1: feature_1413 | BBK1: feature_1414 | BBL1: feature_1415 | BBM1: feature_1416 | BBN1: feature_1417 | BBO1: feature_1418 | BBP1: feature_1419 | BBQ1: feature_1420 | BBR1: feature_1421 | BBS1: feature_1422 | BBT1: feature_1423 | BBU1: feature_1424 | BBV1: feature_1425 | BBW1: feature_1426 | BBX1: feature_1427 | BBY1: feature_1428 | BBZ1: feature_1429 | BCA1: feature_1430 | BCB1: feature_1431 | BCC1: feature_1432 | BCD1: feature_1433 | BCE1: feature_1434 | BCF1: feature_1435 | BCG1: feature_1436 | BCH1: feature_1437 | BCI1: feature_1438 | BCJ1: feature_1439 | BCK1: feature_1440 | BCL1: feature_1441 | BCM1: feature_1442 | BCN1: feature_1443 | BCO1: feature_1444 | BCP1: feature_1445 | BCQ1: feature_1446 | BCR1: feature_1447 | BCS1: feature_1448 | BCT1: feature_1449 | BCU1: feature_1450 | BCV1: feature_1451 | BCW1: feature_1452 | BCX1: feature_1453 | BCY1: feature_1454 | BCZ1: feature_1455 | BDA1: feature_1456 | BDB1: feature_1457 | BDC1: feature_1458 | BDD1: feature_1459 | BDE1: feature_1460 | BDF1: feature_1461 | BDG1: feature_1462 | BDH1: feature_1463 | BDI1: feature_1464 | BDJ1: feature_1465 | BDK1: feature_1466 | BDL1: feature_1467 | BDM1: feature_1468 | BDN1: feature_1469 | BDO1: feature_1470 | BDP1: feature_1471 | BDQ1: feature_1472 | BDR1: feature_1473 | BDS1: feature_1474 | BDT1: feature_1475 | BDU1: feature_1476 | BDV1: feature_1477 | BDW1: feature_1478 | BDX1: feature_1479 | BDY1: feature_1480 | BDZ1: feature_1481 | BEA1: feature_1482 | BEB1: feature_1483 | BEC1: feature_1484 | BED1: feature_1485 | BEE1: feature_1486 | BEF1: feature_1487 | BEG1: feature_1488 | BEH1: feature_1489 | BEI1: feature_1490 | BEJ1: feature_1491 | BEK1: feature_1492 | BEL1: feature_1493 | BEM1: feature_1494 | BEN1: feature_1495 | BEO1: feature_1496 | BEP1: feature_1497 | BEQ1: feature_1498 | BER1: feature_1499 | BES1: feature_1500 | BET1: feature_1501 | BEU1: feature_1502 | BEV1: feature_1503 | BEW1: feature_1504 | BEX1: feature_1505 | BEY1: feature_1506 | BEZ1: feature_1507 | BFA1: feature_1508 | BFB1: feature_1509 | BFC1: feature_1510 | BFD1: feature_1511 | BFE1: feature_1512 | BFF1: feature_1513 | BFG1: feature_1514 | BFH1: feature_1515 | BFI1: feature_1516 | BFJ1: feature_1517 | BFK1: feature_1518 | BFL1: feature_1519 | BFM1: feature_1520 | BFN1: feature_1521 | BFO1: feature_1522 | BFP1: feature_1523 | BFQ1: feature_1524 | BFR1: feature_1525 | BFS1: feature_1526 | BFT1: feature_1527 | BFU1: feature_1528 | BFV1: feature_1529 | BFW1: feature_1530 | BFX1: feature_1531 | BFY1: feature_1532 | BFZ1: feature_1533 | BGA1: feature_1534 | BGB1: feature_1535 | BGC1: feature_1536 | BGD1: feature_1537 | BGE1: feature_1538 | BGF1: feature_1539 | BGG1: feature_1540 | BGH1: feature_1541 | BGI1: feature_1542 | BGJ1: feature_1543 | BGK1: feature_1544 | BGL1: feature_1545 | BGM1: feature_1546 | BGN1: feature_1547 | BGO1: feature_1548 | BGP1: feature_1549 | BGQ1: feature_1550 | BGR1: feature_1551 | BGS1: feature_1552 | BGT1: feature_1553 | BGU1: feature_1554 | BGV1: feature_1555 | BGW1: feature_1556 | BGX1: feature_1557 | BGY1: feature_1558 | BGZ1: feature_1559 | BHA1: feature_1560 | BHB1: feature_1561 | BHC1: feature_1562 | BHD1: feature_1563 | BHE1: feature_1564 | BHF1: feature_1565 | BHG1: feature_1566 | BHH1: feature_1567 | BHI1: feature_1568 | BHJ1: feature_1569 | BHK1: feature_1570 | BHL1: feature_1571 | BHM1: feature_1572 | BHN1: feature_1573 | BHO1: feature_1574 | BHP1: feature_1575 | BHQ1: feature_1576 | BHR1: feature_1577 | BHS1: feature_1578 | BHT1: feature_1579 | BHU1: feature_1580 | BHV1: feature_1581 | BHW1: feature_1582 | BHX1: feature_1583 | BHY1: feature_1584 | BHZ1: feature_1585 | BIA1: feature_1586 | BIB1: feature_1587 | BIC1: feature_1588 | BID1: feature_1589 | BIE1: feature_1590 | BIF1: feature_1591 | BIG1: feature_1592 | BIH1: feature_1593 | BII1: feature_1594 | BIJ1: feature_1595 | BIK1: feature_1596 | BIL1: feature_1597 | BIM1: feature_1598 | BIN1: feature_1599 | BIO1: feature_1600 | BIP1: feature_1601 | BIQ1: feature_1602 | BIR1: feature_1603 | BIS1: feature_1604 | BIT1: feature_1605 | BIU1: feature_1606 | BIV1: feature_1607 | BIW1: feature_1608 | BIX1: feature_1609 | BIY1: feature_1610 | BIZ1: feature_1611 | BJA1: feature_1612 | BJB1: feature_1613 | BJC1: feature_1614 | BJD1: feature_1615 | BJE1: feature_1616 | BJF1: feature_1617 | BJG1: feature_1618 | BJH1: feature_1619 | BJI1: feature_1620 | BJJ1: feature_1621 | BJK1: feature_1622 | BJL1: feature_1623 | BJM1: feature_1624 | BJN1: feature_1625 | BJO1: feature_1626 | BJP1: feature_1627 | BJQ1: feature_1628 | BJR1: feature_1629 | BJS1: feature_1630 | BJT1: feature_1631 | BJU1: feature_1632 | BJV1: feature_1633 | BJW1: feature_1634 | BJX1: feature_1635 | BJY1: feature_1636 | BJZ1: feature_1637 | BKA1: feature_1638 | BKB1: feature_1639 | BKC1: feature_1640 | BKD1: feature_1641 | BKE1: feature_1642 | BKF1: feature_1643 | BKG1: feature_1644 | BKH1: feature_1645 | BKI1: feature_1646 | BKJ1: feature_1647 | BKK1: feature_1648 | BKL1: feature_1649 | BKM1: feature_1650 | BKN1: feature_1651 | BKO1: feature_1652 | BKP1: feature_1653 | BKQ1: feature_1654 | BKR1: feature_1655 | BKS1: feature_1656 | BKT1: feature_1657 | BKU1: feature_1658 | BKV1: feature_1659 | BKW1: feature_1660 | BKX1: feature_1661 | BKY1: feature_1662 | BKZ1: feature_1663 | BLA1: feature_1664 | BLB1: feature_1665 | BLC1: feature_1666 | BLD1: feature_1667 | BLE1: feature_1668 | BLF1: feature_1669 | BLG1: feature_1670 | BLH1: feature_1671 | BLI1: feature_1672 | BLJ1: feature_1673 | BLK1: feature_1674 | BLL1: feature_1675 | BLM1: feature_1676 | BLN1: feature_1677 | BLO1: feature_1678 | BLP1: feature_1679 | BLQ1: feature_1680 | BLR1: feature_1681 | BLS1: feature_1682 | BLT1: feature_1683 | BLU1: feature_1684 | BLV1: feature_1685 | BLW1: feature_1686 | BLX1: feature_1687 | BLY1: feature_1688 | BLZ1: feature_1689 | BMA1: feature_1690 | BMB1: feature_1691 | BMC1: feature_1692 | BMD1: feature_1693 | BME1: feature_1694 | BMF1: feature_1695 | BMG1: feature_1696 | BMH1: feature_1697 | BMI1: feature_1698 | BMJ1: feature_1699 | BMK1: feature_1700 | BML1: feature_1701 | BMM1: feature_1702 | BMN1: feature_1703 | BMO1: feature_1704 | BMP1: feature_1705 | BMQ1: feature_1706 | BMR1: feature_1707 | BMS1: feature_1708 | BMT1: feature_1709 | BMU1: feature_1710 | BMV1: feature_1711 | BMW1: feature_1712 | BMX1: feature_1713 | BMY1: feature_1714 | BMZ1: feature_1715 | BNA1: feature_1716 | BNB1: feature_1717 | BNC1: feature_1718 | BND1: feature_1719 | BNE1: feature_1720 | BNF1: feature_1721 | BNG1: feature_1722 | BNH1: feature_1723 | BNI1: feature_1724 | BNJ1: feature_1725 | BNK1: feature_1726 | BNL1: feature_1727 | BNM1: feature_1728 | BNN1: feature_1729 | BNO1: feature_1730 | BNP1: feature_1731 | BNQ1: feature_1732 | BNR1: feature_1733 | BNS1: feature_1734 | BNT1: feature_1735 | BNU1: feature_1736 | BNV1: feature_1737 | BNW1: feature_1738 | BNX1: feature_1739 | BNY1: feature_1740 | BNZ1: feature_1741 | BOA1: feature_1742 | BOB1: feature_1743 | BOC1: feature_1744 | BOD1: feature_1745 | BOE1: feature_1746 | BOF1: feature_1747 | BOG1: feature_1748 | BOH1: feature_1749 | BOI1: feature_1750 | BOJ1: feature_1751 | BOK1: feature_1752 | BOL1: feature_1753 | BOM1: feature_1754 | BON1: feature_1755 | BOO1: feature_1756 | BOP1: feature_1757 | BOQ1: feature_1758 | BOR1: feature_1759 | BOS1: feature_1760 | BOT1: feature_1761 | BOU1: feature_1762 | BOV1: feature_1763 | BOW1: feature_1764 | BOX1: feature_1765 | BOY1: feature_1766 | BOZ1: feature_1767 | BPA1: feature_1768 | BPB1: feature_1769 | BPC1: feature_1770 | BPD1: feature_1771 | BPE1: feature_1772 | BPF1: feature_1773 | BPG1: feature_1774 | BPH1: feature_1775 | BPI1: feature_1776 | BPJ1: feature_1777 | BPK1: feature_1778 | BPL1: feature_1779 | BPM1: feature_1780 | BPN1: feature_1781 | BPO1: feature_1782 | BPP1: feature_1783 | BPQ1: feature_1784 | BPR1: feature_1785 | BPS1: feature_1786 | BPT1: feature_1787 | BPU1: feature_1788 | BPV1: feature_1789 | BPW1: feature_1790 | BPX1: feature_1791 | BPY1: feature_1792 | BPZ1: feature_1793 | BQA1: feature_1794 | BQB1: feature_1795 | BQC1: feature_1796 | BQD1: feature_1797 | BQE1: feature_1798 | BQF1: feature_1799 | BQG1: feature_1800 | BQH1: feature_1801 | BQI1: feature_1802 | BQJ1: feature_1803 | BQK1: feature_1804 | BQL1: feature_1805 | BQM1: feature_1806 | BQN1: feature_1807 | BQO1: feature_1808 | BQP1: feature_1809 | BQQ1: feature_1810 | BQR1: feature_1811 | BQS1: feature_1812 | BQT1: feature_1813 | BQU1: feature_1814 | BQV1: feature_1815 | BQW1: feature_1816 | BQX1: feature_1817 | BQY1: feature_1818 | BQZ1: feature_1819 | BRA1: feature_1820 | BRB1: feature_1821 | BRC1: feature_1822 | BRD1: feature_1823 | BRE1: feature_1824 | BRF1: feature_1825 | BRG1: feature_1826 | BRH1: feature_1827 | BRI1: feature_1828 | BRJ1: feature_1829 | BRK1: feature_1830 | BRL1: feature_1831 | BRM1: feature_1832 | BRN1: feature_1833 | BRO1: feature_1834 | BRP1: feature_1835 | BRQ1: feature_1836 | BRR1: feature_1837 | BRS1: feature_1838 | BRT1: feature_1839 | BRU1: feature_1840 | BRV1: feature_1841 | BRW1: feature_1842 | BRX1: feature_1843 | BRY1: feature_1844 | BRZ1: feature_1845 | BSA1: feature_1846 | BSB1: feature_1847 | BSC1: feature_1848 | BSD1: feature_1849 | BSE1: feature_1850 | BSF1: feature_1851 | BSG1: feature_1852 | BSH1: feature_1853 | BSI1: feature_1854 | BSJ1: feature_1855 | BSK1: feature_1856 | BSL1: feature_1857 | BSM1: feature_1858 | BSN1: feature_1859 | BSO1: feature_1860 | BSP1: feature_1861 | BSQ1: feature_1862 | BSR1: feature_1863 | BSS1: feature_1864 | BST1: feature_1865 | BSU1: feature_1866 | BSV1: feature_1867 | BSW1: feature_1868 | BSX1: feature_1869 | BSY1: feature_1870 | BSZ1: feature_1871 | BTA1: feature_1872 | BTB1: feature_1873 | BTC1: feature_1874 | BTD1: feature_1875 | BTE1: feature_1876 | BTF1: feature_1877 | BTG1: feature_1878 | BTH1: feature_1879 | BTI1: feature_1880 | BTJ1: feature_1881 | BTK1: feature_1882 | BTL1: feature_1883 | BTM1: feature_1884 | BTN1: feature_1885 | BTO1: feature_1886 | BTP1: feature_1887 | BTQ1: feature_1888 | BTR1: feature_1889 | BTS1: feature_1890 | BTT1: feature_1891 | BTU1: feature_1892 | BTV1: feature_1893 | BTW1: feature_1894 | BTX1: feature_1895 | BTY1: feature_1896 | BTZ1: feature_1897 | BUA1: feature_1898 | BUB1: feature_1899 | BUC1: feature_1900 | BUD1: feature_1901 | BUE1: feature_1902 | BUF1: feature_1903 | BUG1: feature_1904 | BUH1: feature_1905 | BUI1: feature_1906 | BUJ1: feature_1907 | BUK1: feature_1908 | BUL1: feature_1909 | BUM1: feature_1910 | BUN1: feature_1911 | BUO1: feature_1912 | BUP1: feature_1913 | BUQ1: feature_1914 | BUR1: feature_1915 | BUS1: feature_1916 | BUT1: feature_1917 | BUU1: feature_1918 | BUV1: feature_1919 | BUW1: feature_1920 | BUX1: feature_1921 | BUY1: feature_1922 | BUZ1: feature_1923 | BVA1: feature_1924 | BVB1: feature_1925 | BVC1: feature_1926 | BVD1: feature_1927 | BVE1: feature_1928 | BVF1: feature_1929 | BVG1: feature_1930 | BVH1: feature_1931 | BVI1: feature_1932 | BVJ1: feature_1933 | BVK1: feature_1934 | BVL1: feature_1935 | BVM1: feature_1936 | BVN1: feature_1937 | BVO1: feature_1938 | BVP1: feature_1939 | BVQ1: feature_1940 | BVR1: feature_1941 | BVS1: feature_1942 | BVT1: feature_1943 | BVU1: feature_1944 | BVV1: feature_1945 | BVW1: feature_1946 | BVX1: feature_1947 | BVY1: feature_1948 | BVZ1: feature_1949 | BWA1: feature_1950 | BWB1: feature_1951 | BWC1: feature_1952 | BWD1: feature_1953 | BWE1: feature_1954 | BWF1: feature_1955 | BWG1: feature_1956 | BWH1: feature_1957 | BWI1: feature_1958 | BWJ1: feature_1959 | BWK1: feature_1960 | BWL1: feature_1961 | BWM1: feature_1962 | BWN1: feature_1963 | BWO1: feature_1964 | BWP1: feature_1965 | BWQ1: feature_1966 | BWR1: feature_1967 | BWS1: feature_1968 | BWT1: feature_1969 | BWU1: feature_1970 | BWV1: feature_1971 | BWW1: feature_1972 | BWX1: feature_1973 | BWY1: feature_1974 | BWZ1: feature_1975 | BXA1: feature_1976 | BXB1: feature_1977 | BXC1: feature_1978 | BXD1: feature_1979 | BXE1: feature_1980 | BXF1: feature_1981 | BXG1: feature_1982 | BXH1: feature_1983 | BXI1: feature_1984 | BXJ1: feature_1985 | BXK1: feature_1986 | BXL1: feature_1987 | BXM1: feature_1988 | BXN1: feature_1989 | BXO1: feature_1990 | BXP1: feature_1991 | BXQ1: feature_1992 | BXR1: feature_1993 | BXS1: feature_1994 | BXT1: feature_1995 | BXU1: feature_1996 | BXV1: feature_1997 | BXW1: feature_1998 | BXX1: feature_1999 | BXY1: feature_2000 | BXZ1: feature_2001 | BYA1: feature_2002 | BYB1: feature_2003 | BYC1: feature_2004 | BYD1: feature_2005 | BYE1: feature_2006 | BYF1: feature_2007 | BYG1: feature_2008 | BYH1: feature_2009 | BYI1: feature_2010 | BYJ1: feature_2011 | BYK1: feature_2012 | BYL1: feature_2013 | BYM1: feature_2014 | BYN1: feature_2015 | BYO1: feature_2016 | BYP1: feature_2017 | BYQ1: feature_2018 | BYR1: feature_2019 | BYS1: feature_2020 | BYT1: feature_2021 | BYU1: feature_2022 | BYV1: feature_2023 | BYW1: feature_2024 | BYX1: feature_2025 | BYY1: feature_2026 | BYZ1: feature_2027 | BZA1: feature_2028 | BZB1: feature_2029 | BZC1: feature_2030 | BZD1: feature_2031 | BZE1: feature_2032 | BZF1: feature_2033 | BZG1: feature_2034 | BZH1: feature_2035 | BZI1: feature_2036 | BZJ1: feature_2037 | BZK1: feature_2038 | BZL1: feature_2039 | BZM1: feature_2040 | BZN1: feature_2041 | BZO1: feature_2042 | BZP1: feature_2043 | BZQ1: feature_2044 | BZR1: feature_2045 | BZS1: feature_2046 | BZT1: feature_2047 | BZU1: feature_2048 | BZV1: feature_2049 | BZW1: feature_2050 | BZX1: feature_2051 | BZY1: feature_2052 | BZZ1: feature_2053 | CAA1: feature_2054 | CAB1: feature_2055 | CAC1: feature_2056 | CAD1: feature_2057 | CAE1: feature_2058 | CAF1: feature_2059 | CAG1: feature_2060 | CAH1: feature_2061 | CAI1: feature_2062 | CAJ1: feature_2063 | CAK1: feature_2064 | CAL1: feature_2065 | CAM1: feature_2066 | CAN1: feature_2067 | CAO1: feature_2068 | CAP1: feature_2069 | CAQ1: feature_2070 | CAR1: feature_2071 | CAS1: feature_2072 | CAT1: feature_2073 | CAU1: feature_2074 | CAV1: feature_2075 | CAW1: feature_2076 | CAX1: feature_2077 | CAY1: feature_2078 | CAZ1: feature_2079 | CBA1: feature_2080 | CBB1: feature_2081 | CBC1: feature_2082 | CBD1: feature_2083 | CBE1: feature_2084 | CBF1: feature_2085 | CBG1: feature_2086 | CBH1: feature_2087 | CBI1: feature_2088 | CBJ1: feature_2089 | CBK1: feature_2090 | CBL1: feature_2091 | CBM1: feature_2092 | CBN1: feature_2093 | CBO1: feature_2094 | CBP1: feature_2095 | CBQ1: feature_2096 | CBR1: feature_2097 | CBS1: feature_2098 | CBT1: feature_2099 | CBU1: feature_2100 | CBV1: feature_2101 | CBW1: feature_2102 | CBX1: feature_2103 | CBY1: feature_2104 | CBZ1: feature_2105 | CCA1: feature_2106 | CCB1: feature_2107 | CCC1: feature_2108 | CCD1: feature_2109 | CCE1: feature_2110 | CCF1: feature_2111 | CCG1: feature_2112 | CCH1: feature_2113 | CCI1: feature_2114 | CCJ1: feature_2115 | CCK1: feature_2116 | CCL1: feature_2117 | CCM1: feature_2118 | CCN1: feature_2119 | CCO1: feature_2120 | CCP1: feature_2121 | CCQ1: feature_2122 | CCR1: feature_2123 | CCS1: feature_2124 | CCT1: feature_2125 | CCU1: feature_2126 | CCV1: feature_2127 | CCW1: feature_2128 | CCX1: feature_2129 | CCY1: feature_2130 | CCZ1: feature_2131 | CDA1: feature_2132 | CDB1: feature_2133 | CDC1: feature_2134 | CDD1: feature_2135 | CDE1: feature_2136 | CDF1: feature_2137 | CDG1: feature_2138 | CDH1: feature_2139 | CDI1: feature_2140 | CDJ1: feature_2141 | CDK1: feature_2142 | CDL1: feature_2143 | CDM1: feature_2144 | CDN1: feature_2145 | CDO1: feature_2146 | CDP1: feature_2147 | CDQ1: feature_2148 | CDR1: feature_2149 | CDS1: feature_2150 | CDT1: feature_2151 | CDU1: feature_2152 | CDV1: feature_2153 | CDW1: feature_2154 | CDX1: feature_2155 | CDY1: feature_2156 | CDZ1: feature_2157 | CEA1: feature_2158 | CEB1: feature_2159 | CEC1: feature_2160 | CED1: feature_2161 | CEE1: feature_2162 | CEF1: feature_2163 | CEG1: feature_2164 | CEH1: feature_2165 | CEI1: feature_2166 | CEJ1: feature_2167 | CEK1: feature_2168 | CEL1: feature_2169 | CEM1: feature_2170 | CEN1: feature_2171 | CEO1: feature_2172 | CEP1: feature_2173 | CEQ1: feature_2174 | CER1: feature_2175 | CES1: feature_2176 | CET1: feature_2177 | CEU1: feature_2178 | CEV1: feature_2179 | CEW1: feature_2180 | CEX1: feature_2181 | CEY1: feature_2182 | CEZ1: feature_2183 | CFA1: feature_2184 | CFB1: feature_2185 | CFC1: feature_2186 | CFD1: feature_2187 | CFE1: feature_2188 | CFF1: feature_2189 | CFG1: feature_2190 | CFH1: feature_2191 | CFI1: feature_2192 | CFJ1: feature_2193 | CFK1: feature_2194 | CFL1: feature_2195 | CFM1: feature_2196 | CFN1: feature_2197 | CFO1: feature_2198 | CFP1: feature_2199 | CFQ1: feature_2200 | CFR1: feature_2201 | CFS1: feature_2202 | CFT1: feature_2203 | CFU1: feature_2204 | CFV1: feature_2205 | CFW1: feature_2206 | CFX1: feature_2207 | CFY1: feature_2208 | CFZ1: feature_2209 | CGA1: feature_2210 | CGB1: feature_2211 | CGC1: feature_2212 | CGD1: feature_2213 | CGE1: feature_2214 | CGF1: feature_2215 | CGG1: feature_2216 | CGH1: feature_2217 | CGI1: feature_2218 | CGJ1: feature_2219 | CGK1: feature_2220 | CGL1: feature_2221 | CGM1: feature_2222 | CGN1: feature_2223 | CGO1: feature_2224 | CGP1: feature_2225 | CGQ1: feature_2226 | CGR1: feature_2227 | CGS1: feature_2228 | CGT1: feature_2229 | CGU1: feature_2230 | CGV1: feature_2231 | CGW1: feature_2232 | CGX1: feature_2233 | CGY1: feature_2234 | CGZ1: feature_2235 | CHA1: feature_2236 | CHB1: feature_2237 | CHC1: feature_2238 | CHD1: feature_2239 | CHE1: feature_2240 | CHF1: feature_2241 | CHG1: feature_2242 | CHH1: feature_2243 | CHI1: feature_2244 | CHJ1: feature_2245 | CHK1: feature_2246 | CHL1: feature_2247 | CHM1: feature_2248 | CHN1: feature_2249 | CHO1: feature_2250 | CHP1: feature_2251 | CHQ1: feature_2252 | CHR1: feature_2253 | CHS1: feature_2254 | CHT1: feature_2255 | CHU1: feature_2256 | CHV1: feature_2257 | CHW1: feature_2258 | CHX1: feature_2259 | CHY1: feature_2260 | CHZ1: feature_2261 | CIA1: feature_2262 | CIB1: feature_2263 | CIC1: feature_2264 | CID1: feature_2265 | CIE1: feature_2266 | CIF1: feature_2267 | CIG1: feature_2268 | CIH1: feature_2269 | CII1: feature_2270 | CIJ1: feature_2271 | CIK1: feature_2272 | CIL1: feature_2273 | CIM1: feature_2274 | CIN1: feature_2275 | CIO1: feature_2276 | CIP1: feature_2277 | CIQ1: feature_2278 | CIR1: feature_2279 | CIS1: feature_2280 | CIT1: feature_2281 | CIU1: feature_2282 | CIV1: feature_2283 | CIW1: feature_2284 | CIX1: feature_2285 | CIY1: feature_2286 | CIZ1: feature_2287 | CJA1: feature_2288 | CJB1: feature_2289 | CJC1: feature_2290 | CJD1: feature_2291 | CJE1: feature_2292 | CJF1: feature_2293 | CJG1: feature_2294 | CJH1: feature_2295 | CJI1: feature_2296 | CJJ1: feature_2297 | CJK1: feature_2298 | CJL1: feature_2299 | CJM1: feature_2300 | CJN1: feature_2301 | CJO1: feature_2302 | CJP1: feature_2303 | CJQ1: feature_2304 | CJR1: feature_2305 | CJS1: feature_2306 | CJT1: feature_2307 | CJU1: feature_2308 | CJV1: feature_2309 | CJW1: feature_2310 | CJX1: feature_2311 | CJY1: feature_2312 | CJZ1: feature_2313 | CKA1: feature_2314 | CKB1: feature_2315 | CKC1: feature_2316 | CKD1: feature_2317 | CKE1: feature_2318 | CKF1: feature_2319 | CKG1: feature_2320 | CKH1: feature_2321 | CKI1: feature_2322 | CKJ1: feature_2323 | CKK1: feature_2324 | CKL1: feature_2325 | CKM1: feature_2326 | CKN1: feature_2327 | CKO1: feature_2328 | CKP1: feature_2329 | CKQ1: feature_2330 | CKR1: feature_2331 | CKS1: feature_2332 | CKT1: feature_2333 | CKU1: feature_2334 | CKV1: feature_2335 | CKW1: feature_2336 | CKX1: feature_2337 | CKY1: feature_2338 | CKZ1: feature_2339 | CLA1: feature_2340 | CLB1: feature_2341 | CLC1: feature_2342 | CLD1: feature_2343 | CLE1: feature_2344 | CLF1: feature_2345 | CLG1: feature_2346 | CLH1: feature_2347 | CLI1: feature_2348 | CLJ1: feature_2349 | CLK1: feature_2350 | CLL1: feature_2351 | CLM1: feature_2352 | CLN1: feature_2353 | CLO1: feature_2354 | CLP1: feature_2355 | CLQ1: feature_2356 | CLR1: feature_2357 | CLS1: feature_2358 | CLT1: feature_2359 | CLU1: feature_2360 | CLV1: feature_2361 | CLW1: feature_2362 | CLX1: feature_2363 | CLY1: feature_2364 | CLZ1: feature_2365 | CMA1: feature_2366 | CMB1: feature_2367 | CMC1: feature_2368 | CMD1: feature_2369 | CME1: feature_2370 | CMF1: feature_2371 | CMG1: feature_2372 | CMH1: feature_2373 | CMI1: feature_2374 | CMJ1: feature_2375 | CMK1: feature_2376 | CML1: feature_2377 | CMM1: feature_2378 | CMN1: feature_2379 | CMO1: feature_2380 | CMP1: feature_2381 | CMQ1: feature_2382 | CMR1: feature_2383 | CMS1: feature_2384 | CMT1: feature_2385 | CMU1: feature_2386 | CMV1: feature_2387 | CMW1: feature_2388 | CMX1: feature_2389 | CMY1: feature_2390 | CMZ1: feature_2391 | CNA1: feature_2392 | CNB1: feature_2393 | CNC1: feature_2394 | CND1: feature_2395 | CNE1: feature_2396 | CNF1: feature_2397 | CNG1: feature_2398 | CNH1: feature_2399 | CNI1: feature_2400 | CNJ1: feature_2401 | CNK1: feature_2402 | CNL1: feature_2403 | CNM1: feature_2404 | CNN1: feature_2405 | CNO1: feature_2406 | CNP1: feature_2407 | CNQ1: feature_2408 | CNR1: feature_2409 | CNS1: feature_2410 | CNT1: feature_2411 | CNU1: feature_2412 | CNV1: feature_2413 | CNW1: feature_2414 | CNX1: feature_2415 | CNY1: feature_2416 | CNZ1: feature_2417 | COA1: feature_2418 | COB1: feature_2419 | COC1: feature_2420 | COD1: feature_2421 | COE1: feature_2422 | COF1: feature_2423 | COG1: feature_2424 | COH1: feature_2425 | COI1: feature_2426 | COJ1: feature_2427 | COK1: feature_2428 | COL1: feature_2429 | COM1: feature_2430 | CON1: feature_2431 | COO1: feature_2432 | COP1: feature_2433 | COQ1: feature_2434 | COR1: feature_2435 | COS1: feature_2436 | COT1: feature_2437 | COU1: feature_2438 | COV1: feature_2439 | COW1: feature_2440 | COX1: feature_2441 | COY1: feature_2442 | COZ1: feature_2443 | CPA1: feature_2444 | CPB1: feature_2445 | CPC1: feature_2446 | CPD1: feature_2447 | CPE1: feature_2448 | CPF1: feature_2449 | CPG1: feature_2450 | CPH1: feature_2451 | CPI1: feature_2452 | CPJ1: feature_2453 | CPK1: feature_2454 | CPL1: feature_2455 | CPM1: feature_2456 | CPN1: feature_2457 | CPO1: feature_2458 | CPP1: feature_2459 | CPQ1: feature_2460 | CPR1: feature_2461 | CPS1: feature_2462 | CPT1: feature_2463 | CPU1: feature_2464 | CPV1: feature_2465 | CPW1: feature_2466 | CPX1: feature_2467 | CPY1: feature_2468 | CPZ1: feature_2469 | CQA1: feature_2470 | CQB1: feature_2471 | CQC1: feature_2472 | CQD1: feature_2473 | CQE1: feature_2474 | CQF1: feature_2475 | CQG1: feature_2476 | CQH1: feature_2477 | CQI1: feature_2478 | CQJ1: feature_2479 | CQK1: feature_2480 | CQL1: feature_2481 | CQM1: feature_2482 | CQN1: feature_2483 | CQO1: feature_2484 | CQP1: feature_2485 | CQQ1: feature_2486 | CQR1: feature_2487 | CQS1: feature_2488 | CQT1: feature_2489 | CQU1: feature_2490 | CQV1: feature_2491 | CQW1: feature_2492 | CQX1: feature_2493 | CQY1: feature_2494 | CQZ1: feature_2495 | CRA1: feature_2496 | CRB1: feature_2497 | CRC1: feature_2498 | CRD1: feature_2499 | CRE1: feature_2500 | CRF1: feature_2501 | CRG1: feature_2502 | CRH1: feature_2503 | CRI1: feature_2504 | CRJ1: feature_2505 | CRK1: feature_2506 | CRL1: feature_2507 | CRM1: feature_2508 | CRN1: feature_2509 | CRO1: feature_2510 | CRP1: feature_2511 | CRQ1: feature_2512 | CRR1: feature_2513 | CRS1: feature_2514 | CRT1: feature_2515 | CRU1: feature_2516 | CRV1: feature_2517 | CRW1: feature_2518 | CRX1: feature_2519 | CRY1: feature_2520 | CRZ1: feature_2521 | CSA1: feature_2522 | CSB1: feature_2523 | CSC1: feature_2524 | CSD1: feature_2525 | CSE1: feature_2526 | CSF1: feature_2527 | CSG1: feature_2528 | CSH1: feature_2529 | CSI1: feature_2530 | CSJ1: feature_2531 | CSK1: feature_2532 | CSL1: feature_2533 | CSM1: feature_2534 | CSN1: feature_2535 | CSO1: feature_2536 | CSP1: feature_2537 | CSQ1: feature_2538 | CSR1: feature_2539 | CSS1: feature_2540 | CST1: feature_2541 | CSU1: feature_2542 | CSV1: feature_2543 | CSW1: feature_2544 | CSX1: feature_2545 | CSY1: feature_2546 | CSZ1: feature_2547 | CTA1: feature_2548 | CTB1: feature_2549 | CTC1: feature_2550 | CTD1: feature_2551 | CTE1: feature_2552
