Workbook

Sheet merged
A1: Primers | B1: V1–V2-120 | C1: V1–V3-120 | D1: V4-120 | E1: V3–V5-120 | F1: V6–V9-120 | G1: V1–V2-120-stdev | H1: V1–V3-120-stdev | I1: V4-120-stdev | J1: V3–V5-120-stdev | K1: V6–V9-120-stdev | L1: V1–V2-15 | M1: V1–V3-15 | N1: V4-15 | O1: V3–V5-15 | P1: V6–V9-15 | Q1: V1–V2-15-stdev | R1: V1–V3-15-stdev | S1: V4-15-stdev | T1: V3–V5-15-stdev | U1: V6–V9-15-stdev | V1: V1–V2-50 | W1: V1–V3-50 | X1: V4-50 | Y1: V3–V5-50 | Z1: V6–V9-50 | AA1: V1–V2-50-stdev | AB1: V1–V3-50-stdev | AC1: V4-50-stdev | AD1: V3–V5-50-stdev | AE1: V6–V9-50-stdev
A2: 1 | B2: 0 | C2: 0 | D2: 0 | E2: 0 | F2: 0 | G2: 0 | H2: 0 | I2: 0 | J2: 0 | K2: 0 | L2: =AVERAGE('15 strains'!B25,'15 strains'!B67,'15 strains'!B88,'15 strains'!B109,'15 strains'!B130,'15 strains'!B151,'15 strains'!B172,'15 strains'!B193,'15 strains'!B214) -> 0 | M2: =AVERAGE('15 strains'!C25,'15 strains'!C67,'15 strains'!C88,'15 strains'!C109,'15 strains'!C130,'15 strains'!C151,'15 strains'!C172,'15 strains'!C193,'15 strains'!C214) -> 0 | N2: =AVERAGE('15 strains'!D25,'15 strains'!D67,'15 strains'!D88,'15 strains'!D109,'15 strains'!D130,'15 strains'!D151,'15 strains'!D172,'15 strains'!D193,'15 strains'!D214) -> 0 | O2: =AVERAGE('15 strains'!E25,'15 strains'!E67,'15 strains'!E88,'15 strains'!E109,'15 strains'!E130,'15 strains'!E151,'15 strains'!E172,'15 strains'!E193,'15 strains'!E214) -> 0 | P2: =AVERAGE('15 strains'!F25,'15 strains'!F67,'15 strains'!F88,'15 strains'!F109,'15 strains'!F130,'15 strains'!F151,'15 strains'!F172,'15 strains'!F193,'15 strains'!F214) -> 0 | Q2: =STDEV('15 strains'!B25,'15 strains'!B67,'15 strains'!B88,'15 strains'!B109,'15 strains'!B130,'15 strains'!B151,'15 strains'!B172,'15 strains'!B193,'15 strains'!B214) -> 0 | R2: =STDEV('15 strains'!C25,'15 strains'!C67,'15 strains'!C88,'15 strains'!C109,'15 strains'!C130,'15 strains'!C151,'15 strains'!C172,'15 strains'!C193,'15 strains'!C214) -> 0 | S2: =STDEV('15 strains'!D25,'15 strains'!D67,'15 strains'!D88,'15 strains'!D109,'15 strains'!D130,'15 strains'!D151,'15 strains'!D172,'15 strains'!D193,'15 strains'!D214) -> 0 | T2: =STDEV('15 strains'!E25,'15 strains'!E67,'15 strains'!E88,'15 strains'!E109,'15 strains'!E130,'15 strains'!E151,'15 strains'!E172,'15 strains'!E193,'15 strains'!E214) -> 0 | U2: =STDEV('15 strains'!F25,'15 strains'!F67,'15 strains'!F88,'15 strains'!F109,'15 strains'!F130,'15 strains'!F151,'15 strains'!F172,'15 strains'!F193,'15 strains'!F214) -> 0 | V2: =AVERAGE('50 strains'!B25,'50 strains'!B46,'50 strains'!B67,'50 strains'!B88,'50 strains'!B109,'50 strains'!B130,'50 strains'!B151,'50 strains'!B172,'50 strains'!B193,'50 strains'!B214) -> 0 | W2: =AVERAGE('50 strains'!C25,'50 strains'!C46,'50 strains'!C67,'50 strains'!C88,'50 strains'!C109,'50 strains'!C130,'50 strains'!C151,'50 strains'!C172,'50 strains'!C193,'50 strains'!C214) -> 0 | X2: =AVERAGE('50 strains'!D25,'50 strains'!D46,'50 strains'!D67,'50 strains'!D88,'50 strains'!D109,'50 strains'!D130,'50 strains'!D151,'50 strains'!D172,'50 strains'!D193,'50 strains'!D214) -> 0 | Y2: =AVERAGE('50 strains'!E25,'50 strains'!E46,'50 strains'!E67,'50 strains'!E88,'50 strains'!E109,'50 strains'!E130,'50 strains'!E151,'50 strains'!E172,'50 strains'!E193,'50 strains'!E214) -> 0 | Z2: =AVERAGE('50 strains'!F25,'50 strains'!F46,'50 strains'!F67,'50 strains'!F88,'50 strains'!F109,'50 strains'!F130,'50 strains'!F151,'50 strains'!F172,'50 strains'!F193,'50 strains'!F214) -> 0 | AA2: =STDEV('50 strains'!B25,'50 strains'!B46,'50 strains'!B67,'50 strains'!B88,'50 strains'!B109,'50 strains'!B130,'50 strains'!B151,'50 strains'!B172,'50 strains'!B193,'50 strains'!B214) -> 0 | AB2: =STDEV('50 strains'!C25,'50 strains'!C46,'50 strains'!C67,'50 strains'!C88,'50 strains'!C109,'50 strains'!C130,'50 strains'!C151,'50 strains'!C172,'50 strains'!C193,'50 strains'!C214) -> 0 | AC2: =STDEV('50 strains'!D25,'50 strains'!D46,'50 strains'!D67,'50 strains'!D88,'50 strains'!D109,'50 strains'!D130,'50 strains'!D151,'50 strains'!D172,'50 strains'!D193,'50 strains'!D214) -> 0 | AD2: =STDEV('50 strains'!E25,'50 strains'!E46,'50 strains'!E67,'50 strains'!E88,'50 strains'!E109,'50 strains'!E130,'50 strains'!E151,'50 strains'!E172,'50 strains'!E193,'50 strains'!E214) -> 0 | AE2: =STDEV('50 strains'!F25,'50 strains'!F46,'50 strains'!F67,'50 strains'!F88,'50 strains'!F109,'50 strains'!F130,'50 strains'!F151,'50 strains'!F172,'50 strains'!F193,'50 strains'!F214) -> 0
A3: 2 | B3: 0 | C3: 0 | D3: 0 | E3: 0 | F3: 0 | G3: 0 | H3: 0 | I3: 0 | J3: 0 | K3: 0 | L3: =AVERAGE('15 strains'!B26,'15 strains'!B68,'15 strains'!B89,'15 strains'!B110,'15 strains'!B131,'15 strains'!B152,'15 strains'!B173,'15 strains'!B194,'15 strains'!B215) -> 0 | M3: =AVERAGE('15 strains'!C26,'15 strains'!C68,'15 strains'!C89,'15 strains'!C110,'15 strains'!C131,'15 strains'!C152,'15 strains'!C173,'15 strains'!C194,'15 strains'!C215) -> 0 | N3: =AVERAGE('15 strains'!D26,'15 strains'!D68,'15 strains'!D89,'15 strains'!D110,'15 strains'!D131,'15 strains'!D152,'15 strains'!D173,'15 strains'!D194,'15 strains'!D215) -> 0 | O3: =AVERAGE('15 strains'!E26,'15 strains'!E68,'15 strains'!E89,'15 strains'!E110,'15 strains'!E131,'15 strains'!E152,'15 strains'!E173,'15 strains'!E194,'15 strains'!E215) -> 0 | P3: =AVERAGE('15 strains'!F26,'15 strains'!F68,'15 strains'!F89,'15 strains'!F110,'15 strains'!F131,'15 strains'!F152,'15 strains'!F173,'15 strains'!F194,'15 strains'!F215) -> 0 | Q3: =STDEV('15 strains'!B26,'15 strains'!B68,'15 strains'!B89,'15 strains'!B110,'15 strains'!B131,'15 strains'!B152,'15 strains'!B173,'15 strains'!B194,'15 strains'!B215) -> 0 | R3: =STDEV('15 strains'!C26,'15 strains'!C68,'15 strains'!C89,'15 strains'!C110,'15 strains'!C131,'15 strains'!C152,'15 strains'!C173,'15 strains'!C194,'15 strains'!C215) -> 0 | S3: =STDEV('15 strains'!D26,'15 strains'!D68,'15 strains'!D89,'15 strains'!D110,'15 strains'!D131,'15 strains'!D152,'15 strains'!D173,'15 strains'!D194,'15 strains'!D215) -> 0 | T3: =STDEV('15 strains'!E26,'15 strains'!E68,'15 strains'!E89,'15 strains'!E110,'15 strains'!E131,'15 strains'!E152,'15 strains'!E173,'15 strains'!E194,'15 strains'!E215) -> 0 | U3: =STDEV('15 strains'!F26,'15 strains'!F68,'15 strains'!F89,'15 strains'!F110,'15 strains'!F131,'15 strains'!F152,'15 strains'!F173,'15 strains'!F194,'15 strains'!F215) -> 0 | V3: =AVERAGE('50 strains'!B26,'50 strains'!B47,'50 strains'!B68,'50 strains'!B89,'50 strains'!B110,'50 strains'!B131,'50 strains'!B152,'50 strains'!B173,'50 strains'!B194,'50 strains'!B215) -> 0 | W3: =AVERAGE('50 strains'!C26,'50 strains'!C47,'50 strains'!C68,'50 strains'!C89,'50 strains'!C110,'50 strains'!C131,'50 strains'!C152,'50 strains'!C173,'50 strains'!C194,'50 strains'!C215) -> 0 | X3: =AVERAGE('50 strains'!D26,'50 strains'!D47,'50 strains'!D68,'50 strains'!D89,'50 strains'!D110,'50 strains'!D131,'50 strains'!D152,'50 strains'!D173,'50 strains'!D194,'50 strains'!D215) -> 0 | Y3: =AVERAGE('50 strains'!E26,'50 strains'!E47,'50 strains'!E68,'50 strains'!E89,'50 strains'!E110,'50 strains'!E131,'50 strains'!E152,'50 strains'!E173,'50 strains'!E194,'50 strains'!E215) -> 0 | Z3: =AVERAGE('50 strains'!F26,'50 strains'!F47,'50 strains'!F68,'50 strains'!F89,'50 strains'!F110,'50 strains'!F131,'50 strains'!F152,'50 strains'!F173,'50 strains'!F194,'50 strains'!F215) -> 0 | AA3: =STDEV('50 strains'!B26,'50 strains'!B47,'50 strains'!B68,'50 strains'!B89,'50 strains'!B110,'50 strains'!B131,'50 strains'!B152,'50 strains'!B173,'50 strains'!B194,'50 strains'!B215) -> 0 | AB3: =STDEV('50 strains'!C26,'50 strains'!C47,'50 strains'!C68,'50 strains'!C89,'50 strains'!C110,'50 strains'!C131,'50 strains'!C152,'50 strains'!C173,'50 strains'!C194,'50 strains'!C215) -> 0 | AC3: =STDEV('50 strains'!D26,'50 strains'!D47,'50 strains'!D68,'50 strains'!D89,'50 strains'!D110,'50 strains'!D131,'50 strains'!D152,'50 strains'!D173,'50 strains'!D194,'50 strains'!D215) -> 0 | AD3: =STDEV('50 strains'!E26,'50 strains'!E47,'50 strains'!E68,'50 strains'!E89,'50 strains'!E110,'50 strains'!E131,'50 strains'!E152,'50 strains'!E173,'50 strains'!E194,'50 strains'!E215) -> 0 | AE3: =STDEV('50 strains'!F26,'50 strains'!F47,'50 strains'!F68,'50 strains'!F89,'50 strains'!F110,'50 strains'!F131,'50 strains'!F152,'50 strains'!F173,'50 strains'!F194,'50 strains'!F215) -> 0
A4: 3 | B4: 0 | C4: 0 | D4: 0 | E4: 0 | F4: 0 | G4: 0 | H4: 0 | I4: 0 | J4: 0 | K4: 0 | L4: =AVERAGE('15 strains'!B27,'15 strains'!B69,'15 strains'!B90,'15 strains'!B111,'15 strains'!B132,'15 strains'!B153,'15 strains'!B174,'15 strains'!B195,'15 strains'!B216) -> 0 | M4: =AVERAGE('15 strains'!C27,'15 strains'!C69,'15 strains'!C90,'15 strains'!C111,'15 strains'!C132,'15 strains'!C153,'15 strains'!C174,'15 strains'!C195,'15 strains'!C216) -> 0 | N4: =AVERAGE('15 strains'!D27,'15 strains'!D69,'15 strains'!D90,'15 strains'!D111,'15 strains'!D132,'15 strains'!D153,'15 strains'!D174,'15 strains'!D195,'15 strains'!D216) -> 0 | O4: =AVERAGE('15 strains'!E27,'15 strains'!E69,'15 strains'!E90,'15 strains'!E111,'15 strains'!E132,'15 strains'!E153,'15 strains'!E174,'15 strains'!E195,'15 strains'!E216) -> 0 | P4: =AVERAGE('15 strains'!F27,'15 strains'!F69,'15 strains'!F90,'15 strains'!F111,'15 strains'!F132,'15 strains'!F153,'15 strains'!F174,'15 strains'!F195,'15 strains'!F216) -> 0 | Q4: =STDEV('15 strains'!B27,'15 strains'!B69,'15 strains'!B90,'15 strains'!B111,'15 strains'!B132,'15 strains'!B153,'15 strains'!B174,'15 strains'!B195,'15 strains'!B216) -> 0 | R4: =STDEV('15 strains'!C27,'15 strains'!C69,'15 strains'!C90,'15 strains'!C111,'15 strains'!C132,'15 strains'!C153,'15 strains'!C174,'15 strains'!C195,'15 strains'!C216) -> 0 | S4: =STDEV('15 strains'!D27,'15 strains'!D69,'15 strains'!D90,'15 strains'!D111,'15 strains'!D132,'15 strains'!D153,'15 strains'!D174,'15 strains'!D195,'15 strains'!D216) -> 0 | T4: =STDEV('15 strains'!E27,'15 strains'!E69,'15 strains'!E90,'15 strains'!E111,'15 strains'!E132,'15 strains'!E153,'15 strains'!E174,'15 strains'!E195,'15 strains'!E216) -> 0 | U4: =STDEV('15 strains'!F27,'15 strains'!F69,'15 strains'!F90,'15 strains'!F111,'15 strains'!F132,'15 strains'!F153,'15 strains'!F174,'15 strains'!F195,'15 strains'!F216) -> 0 | V4: =AVERAGE('50 strains'!B27,'50 strains'!B48,'50 strains'!B69,'50 strains'!B90,'50 strains'!B111,'50 strains'!B132,'50 strains'!B153,'50 strains'!B174,'50 strains'!B195,'50 strains'!B216) -> 0 | W4: =AVERAGE('50 strains'!C27,'50 strains'!C48,'50 strains'!C69,'50 strains'!C90,'50 strains'!C111,'50 strains'!C132,'50 strains'!C153,'50 strains'!C174,'50 strains'!C195,'50 strains'!C216) -> 0 | X4: =AVERAGE('50 strains'!D27,'50 strains'!D48,'50 strains'!D69,'50 strains'!D90,'50 strains'!D111,'50 strains'!D132,'50 strains'!D153,'50 strains'!D174,'50 strains'!D195,'50 strains'!D216) -> 0 | Y4: =AVERAGE('50 strains'!E27,'50 strains'!E48,'50 strains'!E69,'50 strains'!E90,'50 strains'!E111,'50 strains'!E132,'50 strains'!E153,'50 strains'!E174,'50 strains'!E195,'50 strains'!E216) -> 0 | Z4: =AVERAGE('50 strains'!F27,'50 strains'!F48,'50 strains'!F69,'50 strains'!F90,'50 strains'!F111,'50 strains'!F132,'50 strains'!F153,'50 strains'!F174,'50 strains'!F195,'50 strains'!F216) -> 0 | AA4: =STDEV('50 strains'!B27,'50 strains'!B48,'50 strains'!B69,'50 strains'!B90,'50 strains'!B111,'50 strains'!B132,'50 strains'!B153,'50 strains'!B174,'50 strains'!B195,'50 strains'!B216) -> 0 | AB4: =STDEV('50 strains'!C27,'50 strains'!C48,'50 strains'!C69,'50 strains'!C90,'50 strains'!C111,'50 strains'!C132,'50 strains'!C153,'50 strains'!C174,'50 strains'!C195,'50 strains'!C216) -> 0 | AC4: =STDEV('50 strains'!D27,'50 strains'!D48,'50 strains'!D69,'50 strains'!D90,'50 strains'!D111,'50 strains'!D132,'50 strains'!D153,'50 strains'!D174,'50 strains'!D195,'50 strains'!D216) -> 0 | AD4: =STDEV('50 strains'!E27,'50 strains'!E48,'50 strains'!E69,'50 strains'!E90,'50 strains'!E111,'50 strains'!E132,'50 strains'!E153,'50 strains'!E174,'50 strains'!E195,'50 strains'!E216) -> 0 | AE4: =STDEV('50 strains'!F27,'50 strains'!F48,'50 strains'!F69,'50 strains'!F90,'50 strains'!F111,'50 strains'!F132,'50 strains'!F153,'50 strains'!F174,'50 strains'!F195,'50 strains'!F216) -> 0
A5: 4 | B5: 0 | C5: 0 | D5: 0 | E5: 0 | F5: 0 | G5: 0 | H5: 0 | I5: 0 | J5: 0 | K5: 0 | L5: =AVERAGE('15 strains'!B28,'15 strains'!B70,'15 strains'!B91,'15 strains'!B112,'15 strains'!B133,'15 strains'!B154,'15 strains'!B175,'15 strains'!B196,'15 strains'!B217) -> 0 | M5: =AVERAGE('15 strains'!C28,'15 strains'!C70,'15 strains'!C91,'15 strains'!C112,'15 strains'!C133,'15 strains'!C154,'15 strains'!C175,'15 strains'!C196,'15 strains'!C217) -> 0 | N5: =AVERAGE('15 strains'!D28,'15 strains'!D70,'15 strains'!D91,'15 strains'!D112,'15 strains'!D133,'15 strains'!D154,'15 strains'!D175,'15 strains'!D196,'15 strains'!D217) -> 0 | O5: =AVERAGE('15 strains'!E28,'15 strains'!E70,'15 strains'!E91,'15 strains'!E112,'15 strains'!E133,'15 strains'!E154,'15 strains'!E175,'15 strains'!E196,'15 strains'!E217) -> 0 | P5: =AVERAGE('15 strains'!F28,'15 strains'!F70,'15 strains'!F91,'15 strains'!F112,'15 strains'!F133,'15 strains'!F154,'15 strains'!F175,'15 strains'!F196,'15 strains'!F217) -> 0 | Q5: =STDEV('15 strains'!B28,'15 strains'!B70,'15 strains'!B91,'15 strains'!B112,'15 strains'!B133,'15 strains'!B154,'15 strains'!B175,'15 strains'!B196,'15 strains'!B217) -> 0 | R5: =STDEV('15 strains'!C28,'15 strains'!C70,'15 strains'!C91,'15 strains'!C112,'15 strains'!C133,'15 strains'!C154,'15 strains'!C175,'15 strains'!C196,'15 strains'!C217) -> 0 | S5: =STDEV('15 strains'!D28,'15 strains'!D70,'15 strains'!D91,'15 strains'!D112,'15 strains'!D133,'15 strains'!D154,'15 strains'!D175,'15 strains'!D196,'15 strains'!D217) -> 0 | T5: =STDEV('15 strains'!E28,'15 strains'!E70,'15 strains'!E91,'15 strains'!E112,'15 strains'!E133,'15 strains'!E154,'15 strains'!E175,'15 strains'!E196,'15 strains'!E217) -> 0 | U5: =STDEV('15 strains'!F28,'15 strains'!F70,'15 strains'!F91,'15 strains'!F112,'15 strains'!F133,'15 strains'!F154,'15 strains'!F175,'15 strains'!F196,'15 strains'!F217) -> 0 | V5: =AVERAGE('50 strains'!B28,'50 strains'!B49,'50 strains'!B70,'50 strains'!B91,'50 strains'!B112,'50 strains'!B133,'50 strains'!B154,'50 strains'!B175,'50 strains'!B196,'50 strains'!B217) -> 0 | W5: =AVERAGE('50 strains'!C28,'50 strains'!C49,'50 strains'!C70,'50 strains'!C91,'50 strains'!C112,'50 strains'!C133,'50 strains'!C154,'50 strains'!C175,'50 strains'!C196,'50 strains'!C217) -> 0 | X5: =AVERAGE('50 strains'!D28,'50 strains'!D49,'50 strains'!D70,'50 strains'!D91,'50 strains'!D112,'50 strains'!D133,'50 strains'!D154,'50 strains'!D175,'50 strains'!D196,'50 strains'!D217) -> 0 | Y5: =AVERAGE('50 strains'!E28,'50 strains'!E49,'50 strains'!E70,'50 strains'!E91,'50 strains'!E112,'50 strains'!E133,'50 strains'!E154,'50 strains'!E175,'50 strains'!E196,'50 strains'!E217) -> 0 | Z5: =AVERAGE('50 strains'!F28,'50 strains'!F49,'50 strains'!F70,'50 strains'!F91,'50 strains'!F112,'50 strains'!F133,'50 strains'!F154,'50 strains'!F175,'50 strains'!F196,'50 strains'!F217) -> 0 | AA5: =STDEV('50 strains'!B28,'50 strains'!B49,'50 strains'!B70,'50 strains'!B91,'50 strains'!B112,'50 strains'!B133,'50 strains'!B154,'50 strains'!B175,'50 strains'!B196,'50 strains'!B217) -> 0 | AB5: =STDEV('50 strains'!C28,'50 strains'!C49,'50 strains'!C70,'50 strains'!C91,'50 strains'!C112,'50 strains'!C133,'50 strains'!C154,'50 strains'!C175,'50 strains'!C196,'50 strains'!C217) -> 0 | AC5: =STDEV('50 strains'!D28,'50 strains'!D49,'50 strains'!D70,'50 strains'!D91,'50 strains'!D112,'50 strains'!D133,'50 strains'!D154,'50 strains'!D175,'50 strains'!D196,'50 strains'!D217) -> 0 | AD5: =STDEV('50 strains'!E28,'50 strains'!E49,'50 strains'!E70,'50 strains'!E91,'50 strains'!E112,'50 strains'!E133,'50 strains'!E154,'50 strains'!E175,'50 strains'!E196,'50 strains'!E217) -> 0 | AE5: =STDEV('50 strains'!F28,'50 strains'!F49,'50 strains'!F70,'50 strains'!F91,'50 strains'!F112,'50 strains'!F133,'50 strains'!F154,'50 strains'!F175,'50 strains'!F196,'50 strains'!F217) -> 0
A6: 5 | B6: 0.0018181818 | C6: 0 | D6: 0 | E6: 0.010833333 | F6: 0.026315789 | G6: 0 | H6: 0 | I6: 0 | J6: 0 | K6: 0 | L6: =AVERAGE('15 strains'!B29,'15 strains'!B71,'15 strains'!B92,'15 strains'!B113,'15 strains'!B134,'15 strains'!B155,'15 strains'!B176,'15 strains'!B197,'15 strains'!B218) -> 0.0014814815 | M6: =AVERAGE('15 strains'!C29,'15 strains'!C71,'15 strains'!C92,'15 strains'!C113,'15 strains'!C134,'15 strains'!C155,'15 strains'!C176,'15 strains'!C197,'15 strains'!C218) -> 0 | N6: =AVERAGE('15 strains'!D29,'15 strains'!D71,'15 strains'!D92,'15 strains'!D113,'15 strains'!D134,'15 strains'!D155,'15 strains'!D176,'15 strains'!D197,'15 strains'!D218) -> 0 | O6: =AVERAGE('15 strains'!E29,'15 strains'!E71,'15 strains'!E92,'15 strains'!E113,'15 strains'!E134,'15 strains'!E155,'15 strains'!E176,'15 strains'!E197,'15 strains'!E218) -> 0.01037037 | P6: =AVERAGE('15 strains'!F29,'15 strains'!F71,'15 strains'!F92,'15 strains'!F113,'15 strains'!F134,'15 strains'!F155,'15 strains'!F176,'15 strains'!F197,'15 strains'!F218) -> 0.026666667 | Q6: =STDEV('15 strains'!B29,'15 strains'!B71,'15 strains'!B92,'15 strains'!B113,'15 strains'!B134,'15 strains'!B155,'15 strains'!B176,'15 strains'!B197,'15 strains'!B218) -> 0.0044444444 | R6: =STDEV('15 strains'!C29,'15 strains'!C71,'15 strains'!C92,'15 strains'!C113,'15 strains'!C134,'15 strains'!C155,'15 strains'!C176,'15 strains'!C197,'15 strains'!C218) -> 0 | S6: =STDEV('15 strains'!D29,'15 strains'!D71,'15 strains'!D92,'15 strains'!D113,'15 strains'!D134,'15 strains'!D155,'15 strains'!D176,'15 strains'!D197,'15 strains'!D218) -> 0 | T6: =STDEV('15 strains'!E29,'15 strains'!E71,'15 strains'!E92,'15 strains'!E113,'15 strains'!E134,'15 strains'!E155,'15 strains'!E176,'15 strains'!E197,'15 strains'!E218) -> 0.01735611 | U6: =STDEV('15 strains'!F29,'15 strains'!F71,'15 strains'!F92,'15 strains'!F113,'15 strains'!F134,'15 strains'!F155,'15 strains'!F176,'15 strains'!F197,'15 strains'!F218) -> 0.021081851 | V6: =AVERAGE('50 strains'!B29,'50 strains'!B50,'50 strains'!B71,'50 strains'!B92,'50 strains'!B113,'50 strains'!B134,'50 strains'!B155,'50 strains'!B176,'50 strains'!B197,'50 strains'!B218) -> 0.002 | W6: =AVERAGE('50 strains'!C29,'50 strains'!C50,'50 strains'!C71,'50 strains'!C92,'50 strains'!C113,'50 strains'!C134,'50 strains'!C155,'50 strains'!C176,'50 strains'!C197,'50 strains'!C218) -> 0 | X6: =AVERAGE('50 strains'!D29,'50 strains'!D50,'50 strains'!D71,'50 strains'!D92,'50 strains'!D113,'50 strains'!D134,'50 strains'!D155,'50 strains'!D176,'50 strains'!D197,'50 strains'!D218) -> 0 | Y6: =AVERAGE('50 strains'!E29,'50 strains'!E50,'50 strains'!E71,'50 strains'!E92,'50 strains'!E113,'50 strains'!E134,'50 strains'!E155,'50 strains'!E176,'50 strains'!E197,'50 strains'!E218) -> 0.0132 | Z6: =AVERAGE('50 strains'!F29,'50 strains'!F50,'50 strains'!F71,'50 strains'!F92,'50 strains'!F113,'50 strains'!F134,'50 strains'!F155,'50 strains'!F176,'50 strains'!F197,'50 strains'!F218) -> 0.028 | AA6: =STDEV('50 strains'!B29,'50 strains'!B50,'50 strains'!B71,'50 strains'!B92,'50 strains'!B113,'50 strains'!B134,'50 strains'!B155,'50 strains'!B176,'50 strains'!B197,'50 strains'!B218) -> 0.0021081851 | AB6: =STDEV('50 strains'!C29,'50 strains'!C50,'50 strains'!C71,'50 strains'!C92,'50 strains'!C113,'50 strains'!C134,'50 strains'!C155,'50 strains'!C176,'50 strains'!C197,'50 strains'!C218) -> 0 | AC6: =STDEV('50 strains'!D29,'50 strains'!D50,'50 strains'!D71,'50 strains'!D92,'50 strains'!D113,'50 strains'!D134,'50 strains'!D155,'50 strains'!D176,'50 strains'!D197,'50 strains'!D218) -> 0 | AD6: =STDEV('50 strains'!E29,'50 strains'!E50,'50 strains'!E71,'50 strains'!E92,'50 strains'!E113,'50 strains'!E134,'50 strains'!E155,'50 strains'!E176,'50 strains'!E197,'50 strains'!E218) -> 0.0081758452 | AE6: =STDEV('50 strains'!F29,'50 strains'!F50,'50 strains'!F71,'50 strains'!F92,'50 strains'!F113,'50 strains'!F134,'50 strains'!F155,'50 strains'!F176,'50 strains'!F197,'50 strains'!F218) -> 0.012220202
A7: 6 | B7: 0.068181818 | C7: 0 | D7: 0 | E7: 0.073611111 | F7: 0.074561404 | G7: 0 | H7: 0 | I7: 0 | J7: 0 | K7: 0 | L7: =AVERAGE('15 strains'!B30,'15 strains'!B72,'15 strains'!B93,'15 strains'!B114,'15 strains'!B135,'15 strains'!B156,'15 strains'!B177,'15 strains'!B198,'15 strains'!B219) -> 0.058024691 | M7: =AVERAGE('15 strains'!C30,'15 strains'!C72,'15 strains'!C93,'15 strains'!C114,'15 strains'!C135,'15 strains'!C156,'15 strains'!C177,'15 strains'!C198,'15 strains'!C219) -> 0 | N7: =AVERAGE('15 strains'!D30,'15 strains'!D72,'15 strains'!D93,'15 strains'!D114,'15 strains'!D135,'15 strains'!D156,'15 strains'!D177,'15 strains'!D198,'15 strains'!D219) -> 0 | O7: =AVERAGE('15 strains'!E30,'15 strains'!E72,'15 strains'!E93,'15 strains'!E114,'15 strains'!E135,'15 strains'!E156,'15 strains'!E177,'15 strains'!E198,'15 strains'!E219) -> 0.071604938 | P7: =AVERAGE('15 strains'!F30,'15 strains'!F72,'15 strains'!F93,'15 strains'!F114,'15 strains'!F135,'15 strains'!F156,'15 strains'!F177,'15 strains'!F198,'15 strains'!F219) -> 0.071604938 | Q7: =STDEV('15 strains'!B30,'15 strains'!B72,'15 strains'!B93,'15 strains'!B114,'15 strains'!B135,'15 strains'!B156,'15 strains'!B177,'15 strains'!B198,'15 strains'!B219) -> 0.016459619 | R7: =STDEV('15 strains'!C30,'15 strains'!C72,'15 strains'!C93,'15 strains'!C114,'15 strains'!C135,'15 strains'!C156,'15 strains'!C177,'15 strains'!C198,'15 strains'!C219) -> 0 | S7: =STDEV('15 strains'!D30,'15 strains'!D72,'15 strains'!D93,'15 strains'!D114,'15 strains'!D135,'15 strains'!D156,'15 strains'!D177,'15 strains'!D198,'15 strains'!D219) -> 0 | T7: =STDEV('15 strains'!E30,'15 strains'!E72,'15 strains'!E93,'15 strains'!E114,'15 strains'!E135,'15 strains'!E156,'15 strains'!E177,'15 strains'!E198,'15 strains'!E219) -> 0.016769232 | U7: =STDEV('15 strains'!F30,'15 strains'!F72,'15 strains'!F93,'15 strains'!F114,'15 strains'!F135,'15 strains'!F156,'15 strains'!F177,'15 strains'!F198,'15 strains'!F219) -> 0.02011626 | V7: =AVERAGE('50 strains'!B30,'50 strains'!B51,'50 strains'!B72,'50 strains'!B93,'50 strains'!B114,'50 strains'!B135,'50 strains'!B156,'50 strains'!B177,'50 strains'!B198,'50 strains'!B219) -> 0.068333333 | W7: =AVERAGE('50 strains'!C30,'50 strains'!C51,'50 strains'!C72,'50 strains'!C93,'50 strains'!C114,'50 strains'!C135,'50 strains'!C156,'50 strains'!C177,'50 strains'!C198,'50 strains'!C219) -> 0 | X7: =AVERAGE('50 strains'!D30,'50 strains'!D51,'50 strains'!D72,'50 strains'!D93,'50 strains'!D114,'50 strains'!D135,'50 strains'!D156,'50 strains'!D177,'50 strains'!D198,'50 strains'!D219) -> 0 | Y7: =AVERAGE('50 strains'!E30,'50 strains'!E51,'50 strains'!E72,'50 strains'!E93,'50 strains'!E114,'50 strains'!E135,'50 strains'!E156,'50 strains'!E177,'50 strains'!E198,'50 strains'!E219) -> 0.071333333 | Z7: =AVERAGE('50 strains'!F30,'50 strains'!F51,'50 strains'!F72,'50 strains'!F93,'50 strains'!F114,'50 strains'!F135,'50 strains'!F156,'50 strains'!F177,'50 strains'!F198,'50 strains'!F219) -> 0.078333333 | AA7: =STDEV('50 strains'!B30,'50 strains'!B51,'50 strains'!B72,'50 strains'!B93,'50 strains'!B114,'50 strains'!B135,'50 strains'!B156,'50 strains'!B177,'50 strains'!B198,'50 strains'!B219) -> 0.011138854 | AB7: =STDEV('50 strains'!C30,'50 strains'!C51,'50 strains'!C72,'50 strains'!C93,'50 strains'!C114,'50 strains'!C135,'50 strains'!C156,'50 strains'!C177,'50 strains'!C198,'50 strains'!C219) -> 0 | AC7: =STDEV('50 strains'!D30,'50 strains'!D51,'50 strains'!D72,'50 strains'!D93,'50 strains'!D114,'50 strains'!D135,'50 strains'!D156,'50 strains'!D177,'50 strains'!D198,'50 strains'!D219) -> 0 | AD7: =STDEV('50 strains'!E30,'50 strains'!E51,'50 strains'!E72,'50 strains'!E93,'50 strains'!E114,'50 strains'!E135,'50 strains'!E156,'50 strains'!E177,'50 strains'!E198,'50 strains'!E219) -> 0.0116746 | AE7: =STDEV('50 strains'!F30,'50 strains'!F51,'50 strains'!F72,'50 strains'!F93,'50 strains'!F114,'50 strains'!F135,'50 strains'!F156,'50 strains'!F177,'50 strains'!F198,'50 strains'!F219) -> 0.012692955
A8: 7 | B8: 0.1012987 | C8: 0 | D8: 0 | E8: 0.10714286 | F8: 0.068922306 | G8: 0 | H8: 0 | I8: 0 | J8: 0 | K8: 0 | L8: =AVERAGE('15 strains'!B31,'15 strains'!B73,'15 strains'!B94,'15 strains'!B115,'15 strains'!B136,'15 strains'!B157,'15 strains'!B178,'15 strains'!B199,'15 strains'!B220) -> 0.098412698 | M8: =AVERAGE('15 strains'!C31,'15 strains'!C73,'15 strains'!C94,'15 strains'!C115,'15 strains'!C136,'15 strains'!C157,'15 strains'!C178,'15 strains'!C199,'15 strains'!C220) -> 0 | N8: =AVERAGE('15 strains'!D31,'15 strains'!D73,'15 strains'!D94,'15 strains'!D115,'15 strains'!D136,'15 strains'!D157,'15 strains'!D178,'15 strains'!D199,'15 strains'!D220) -> 0 | O8: =AVERAGE('15 strains'!E31,'15 strains'!E73,'15 strains'!E94,'15 strains'!E115,'15 strains'!E136,'15 strains'!E157,'15 strains'!E178,'15 strains'!E199,'15 strains'!E220) -> 0.094179894 | P8: =AVERAGE('15 strains'!F31,'15 strains'!F73,'15 strains'!F94,'15 strains'!F115,'15 strains'!F136,'15 strains'!F157,'15 strains'!F178,'15 strains'!F199,'15 strains'!F220) -> 0.068783069 | Q8: =STDEV('15 strains'!B31,'15 strains'!B73,'15 strains'!B94,'15 strains'!B115,'15 strains'!B136,'15 strains'!B157,'15 strains'!B178,'15 strains'!B199,'15 strains'!B220) -> 0.029354352 | R8: =STDEV('15 strains'!C31,'15 strains'!C73,'15 strains'!C94,'15 strains'!C115,'15 strains'!C136,'15 strains'!C157,'15 strains'!C178,'15 strains'!C199,'15 strains'!C220) -> 0 | S8: =STDEV('15 strains'!D31,'15 strains'!D73,'15 strains'!D94,'15 strains'!D115,'15 strains'!D136,'15 strains'!D157,'15 strains'!D178,'15 strains'!D199,'15 strains'!D220) -> 0 | T8: =STDEV('15 strains'!E31,'15 strains'!E73,'15 strains'!E94,'15 strains'!E115,'15 strains'!E136,'15 strains'!E157,'15 strains'!E178,'15 strains'!E199,'15 strains'!E220) -> 0.021531206 | U8: =STDEV('15 strains'!F31,'15 strains'!F73,'15 strains'!F94,'15 strains'!F115,'15 strains'!F136,'15 strains'!F157,'15 strains'!F178,'15 strains'!F199,'15 strains'!F220) -> 0.020077953 | V8: =AVERAGE('50 strains'!B31,'50 strains'!B52,'50 strains'!B73,'50 strains'!B94,'50 strains'!B115,'50 strains'!B136,'50 strains'!B157,'50 strains'!B178,'50 strains'!B199,'50 strains'!B220) -> 0.099428571 | W8: =AVERAGE('50 strains'!C31,'50 strains'!C52,'50 strains'!C73,'50 strains'!C94,'50 strains'!C115,'50 strains'!C136,'50 strains'!C157,'50 strains'!C178,'50 strains'!C199,'50 strains'!C220) -> 0 | X8: =AVERAGE('50 strains'!D31,'50 strains'!D52,'50 strains'!D73,'50 strains'!D94,'50 strains'!D115,'50 strains'!D136,'50 strains'!D157,'50 strains'!D178,'50 strains'!D199,'50 strains'!D220) -> 0 | Y8: =AVERAGE('50 strains'!E31,'50 strains'!E52,'50 strains'!E73,'50 strains'!E94,'50 strains'!E115,'50 strains'!E136,'50 strains'!E157,'50 strains'!E178,'50 strains'!E199,'50 strains'!E220) -> 0.10342857 | Z8: =AVERAGE('50 strains'!F31,'50 strains'!F52,'50 strains'!F73,'50 strains'!F94,'50 strains'!F115,'50 strains'!F136,'50 strains'!F157,'50 strains'!F178,'50 strains'!F199,'50 strains'!F220) -> 0.072285714 | AA8: =STDEV('50 strains'!B31,'50 strains'!B52,'50 strains'!B73,'50 strains'!B94,'50 strains'!B115,'50 strains'!B136,'50 strains'!B157,'50 strains'!B178,'50 strains'!B199,'50 strains'!B220) -> 0.012106856 | AB8: =STDEV('50 strains'!C31,'50 strains'!C52,'50 strains'!C73,'50 strains'!C94,'50 strains'!C115,'50 strains'!C136,'50 strains'!C157,'50 strains'!C178,'50 strains'!C199,'50 strains'!C220) -> 0 | AC8: =STDEV('50 strains'!D31,'50 strains'!D52,'50 strains'!D73,'50 strains'!D94,'50 strains'!D115,'50 strains'!D136,'50 strains'!D157,'50 strains'!D178,'50 strains'!D199,'50 strains'!D220) -> 0 | AD8: =STDEV('50 strains'!E31,'50 strains'!E52,'50 strains'!E73,'50 strains'!E94,'50 strains'!E115,'50 strains'!E136,'50 strains'!E157,'50 strains'!E178,'50 strains'!E199,'50 strains'!E220) -> 0.015226186 | AE8: =STDEV('50 strains'!F31,'50 strains'!F52,'50 strains'!F73,'50 strains'!F94,'50 strains'!F115,'50 strains'!F136,'50 strains'!F157,'50 strains'!F178,'50 strains'!F199,'50 strains'!F220) -> 0.012200145
A9: 8 | B9: 0.11818182 | C9: 0.125 | D9: 0.089583333 | E9: 0.125 | F9: 0.12828947 | G9: 0 | H9: 0 | I9: 0 | J9: 0 | K9: 0 | L9: =AVERAGE('15 strains'!B32,'15 strains'!B74,'15 strains'!B95,'15 strains'!B116,'15 strains'!B137,'15 strains'!B158,'15 strains'!B179,'15 strains'!B200,'15 strains'!B221) -> 0.11111111 | M9: =AVERAGE('15 strains'!C32,'15 strains'!C74,'15 strains'!C95,'15 strains'!C116,'15 strains'!C137,'15 strains'!C158,'15 strains'!C179,'15 strains'!C200,'15 strains'!C221) -> 0.125 | N9: =AVERAGE('15 strains'!D32,'15 strains'!D74,'15 strains'!D95,'15 strains'!D116,'15 strains'!D137,'15 strains'!D158,'15 strains'!D179,'15 strains'!D200,'15 strains'!D221) -> 0.084259259 | O9: =AVERAGE('15 strains'!E32,'15 strains'!E74,'15 strains'!E95,'15 strains'!E116,'15 strains'!E137,'15 strains'!E158,'15 strains'!E179,'15 strains'!E200,'15 strains'!E221) -> 0.12314815 | P9: =AVERAGE('15 strains'!F32,'15 strains'!F74,'15 strains'!F95,'15 strains'!F116,'15 strains'!F137,'15 strains'!F158,'15 strains'!F179,'15 strains'!F200,'15 strains'!F221) -> 0.13148148 | Q9: =STDEV('15 strains'!B32,'15 strains'!B74,'15 strains'!B95,'15 strains'!B116,'15 strains'!B137,'15 strains'!B158,'15 strains'!B179,'15 strains'!B200,'15 strains'!B221) -> 0.019982631 | R9: =STDEV('15 strains'!C32,'15 strains'!C74,'15 strains'!C95,'15 strains'!C116,'15 strains'!C137,'15 strains'!C158,'15 strains'!C179,'15 strains'!C200,'15 strains'!C221) -> 0 | S9: =STDEV('15 strains'!D32,'15 strains'!D74,'15 strains'!D95,'15 strains'!D116,'15 strains'!D137,'15 strains'!D158,'15 strains'!D179,'15 strains'!D200,'15 strains'!D221) -> 0.014698618 | T9: =STDEV('15 strains'!E32,'15 strains'!E74,'15 strains'!E95,'15 strains'!E116,'15 strains'!E137,'15 strains'!E158,'15 strains'!E179,'15 strains'!E200,'15 strains'!E221) -> 0.0055555556 | U9: =STDEV('15 strains'!F32,'15 strains'!F74,'15 strains'!F95,'15 strains'!F116,'15 strains'!F137,'15 strains'!F158,'15 strains'!F179,'15 strains'!F200,'15 strains'!F221) -> 0.019444444 | V9: =AVERAGE('50 strains'!B32,'50 strains'!B53,'50 strains'!B74,'50 strains'!B95,'50 strains'!B116,'50 strains'!B137,'50 strains'!B158,'50 strains'!B179,'50 strains'!B200,'50 strains'!B221) -> 0.1185 | W9: =AVERAGE('50 strains'!C32,'50 strains'!C53,'50 strains'!C74,'50 strains'!C95,'50 strains'!C116,'50 strains'!C137,'50 strains'!C158,'50 strains'!C179,'50 strains'!C200,'50 strains'!C221) -> 0.125 | X9: =AVERAGE('50 strains'!D32,'50 strains'!D53,'50 strains'!D74,'50 strains'!D95,'50 strains'!D116,'50 strains'!D137,'50 strains'!D158,'50 strains'!D179,'50 strains'!D200,'50 strains'!D221) -> 0.088 | Y9: =AVERAGE('50 strains'!E32,'50 strains'!E53,'50 strains'!E74,'50 strains'!E95,'50 strains'!E116,'50 strains'!E137,'50 strains'!E158,'50 strains'!E179,'50 strains'!E200,'50 strains'!E221) -> 0.125 | Z9: =AVERAGE('50 strains'!F32,'50 strains'!F53,'50 strains'!F74,'50 strains'!F95,'50 strains'!F116,'50 strains'!F137,'50 strains'!F158,'50 strains'!F179,'50 strains'!F200,'50 strains'!F221) -> 0.1295 | AA9: =STDEV('50 strains'!B32,'50 strains'!B53,'50 strains'!B74,'50 strains'!B95,'50 strains'!B116,'50 strains'!B137,'50 strains'!B158,'50 strains'!B179,'50 strains'!B200,'50 strains'!B221) -> 0.005027701 | AB9: =STDEV('50 strains'!C32,'50 strains'!C53,'50 strains'!C74,'50 strains'!C95,'50 strains'!C116,'50 strains'!C137,'50 strains'!C158,'50 strains'!C179,'50 strains'!C200,'50 strains'!C221) -> 0 | AC9: =STDEV('50 strains'!D32,'50 strains'!D53,'50 strains'!D74,'50 strains'!D95,'50 strains'!D116,'50 strains'!D137,'50 strains'!D158,'50 strains'!D179,'50 strains'!D200,'50 strains'!D221) -> 0.00831665 | AD9: =STDEV('50 strains'!E32,'50 strains'!E53,'50 strains'!E74,'50 strains'!E95,'50 strains'!E116,'50 strains'!E137,'50 strains'!E158,'50 strains'!E179,'50 strains'!E200,'50 strains'!E221) -> 0 | AE9: =STDEV('50 strains'!F32,'50 strains'!F53,'50 strains'!F74,'50 strains'!F95,'50 strains'!F116,'50 strains'!F137,'50 strains'!F158,'50 strains'!F179,'50 strains'!F200,'50 strains'!F221) -> 0.012791056
A10: 9 | B10: 0.12020202 | C10: 0.11111111 | D10: 0.11111111 | E10: 0.175 | F10: 0.1754386 | G10: 0 | H10: 0 | I10: 0 | J10: 0 | K10: 0 | L10: =AVERAGE('15 strains'!B33,'15 strains'!B75,'15 strains'!B96,'15 strains'!B117,'15 strains'!B138,'15 strains'!B159,'15 strains'!B180,'15 strains'!B201,'15 strains'!B222) -> 0.11358025 | M10: =AVERAGE('15 strains'!C33,'15 strains'!C75,'15 strains'!C96,'15 strains'!C117,'15 strains'!C138,'15 strains'!C159,'15 strains'!C180,'15 strains'!C201,'15 strains'!C222) -> 0.11111111 | N10: =AVERAGE('15 strains'!D33,'15 strains'!D75,'15 strains'!D96,'15 strains'!D117,'15 strains'!D138,'15 strains'!D159,'15 strains'!D180,'15 strains'!D201,'15 strains'!D222) -> 0.11111111 | O10: =AVERAGE('15 strains'!E33,'15 strains'!E75,'15 strains'!E96,'15 strains'!E117,'15 strains'!E138,'15 strains'!E159,'15 strains'!E180,'15 strains'!E201,'15 strains'!E222) -> 0.16625514 | P10: =AVERAGE('15 strains'!F33,'15 strains'!F75,'15 strains'!F96,'15 strains'!F117,'15 strains'!F138,'15 strains'!F159,'15 strains'!F180,'15 strains'!F201,'15 strains'!F222) -> 0.15802469 | Q10: =STDEV('15 strains'!B33,'15 strains'!B75,'15 strains'!B96,'15 strains'!B117,'15 strains'!B138,'15 strains'!B159,'15 strains'!B180,'15 strains'!B201,'15 strains'!B222) -> 0.025660012 | R10: =STDEV('15 strains'!C33,'15 strains'!C75,'15 strains'!C96,'15 strains'!C117,'15 strains'!C138,'15 strains'!C159,'15 strains'!C180,'15 strains'!C201,'15 strains'!C222) -> 2.9439234e-17 | S10: =STDEV('15 strains'!D33,'15 strains'!D75,'15 strains'!D96,'15 strains'!D117,'15 strains'!D138,'15 strains'!D159,'15 strains'!D180,'15 strains'!D201,'15 strains'!D222) -> 2.9439234e-17 | T10: =STDEV('15 strains'!E33,'15 strains'!E75,'15 strains'!E96,'15 strains'!E117,'15 strains'!E138,'15 strains'!E159,'15 strains'!E180,'15 strains'!E201,'15 strains'!E222) -> 0.016609412 | U10: =STDEV('15 strains'!F33,'15 strains'!F75,'15 strains'!F96,'15 strains'!F117,'15 strains'!F138,'15 strains'!F159,'15 strains'!F180,'15 strains'!F201,'15 strains'!F222) -> 0.019598158 | V10: =AVERAGE('50 strains'!B33,'50 strains'!B54,'50 strains'!B75,'50 strains'!B96,'50 strains'!B117,'50 strains'!B138,'50 strains'!B159,'50 strains'!B180,'50 strains'!B201,'50 strains'!B222) -> 0.11888889 | W10: =AVERAGE('50 strains'!C33,'50 strains'!C54,'50 strains'!C75,'50 strains'!C96,'50 strains'!C117,'50 strains'!C138,'50 strains'!C159,'50 strains'!C180,'50 strains'!C201,'50 strains'!C222) -> 0.11111111 | X10: =AVERAGE('50 strains'!D33,'50 strains'!D54,'50 strains'!D75,'50 strains'!D96,'50 strains'!D117,'50 strains'!D138,'50 strains'!D159,'50 strains'!D180,'50 strains'!D201,'50 strains'!D222) -> 0.11111111 | Y10: =AVERAGE('50 strains'!E33,'50 strains'!E54,'50 strains'!E75,'50 strains'!E96,'50 strains'!E117,'50 strains'!E138,'50 strains'!E159,'50 strains'!E180,'50 strains'!E201,'50 strains'!E222) -> 0.166 | Z10: =AVERAGE('50 strains'!F33,'50 strains'!F54,'50 strains'!F75,'50 strains'!F96,'50 strains'!F117,'50 strains'!F138,'50 strains'!F159,'50 strains'!F180,'50 strains'!F201,'50 strains'!F222) -> 0.176 | AA10: =STDEV('50 strains'!B33,'50 strains'!B54,'50 strains'!B75,'50 strains'!B96,'50 strains'!B117,'50 strains'!B138,'50 strains'!B159,'50 strains'!B180,'50 strains'!B201,'50 strains'!B222) -> 0.0081312957 | AB10: =STDEV('50 strains'!C33,'50 strains'!C54,'50 strains'!C75,'50 strains'!C96,'50 strains'!C117,'50 strains'!C138,'50 strains'!C159,'50 strains'!C180,'50 strains'!C201,'50 strains'!C222) -> 2.9256946e-17 | AC10: =STDEV('50 strains'!D33,'50 strains'!D54,'50 strains'!D75,'50 strains'!D96,'50 strains'!D117,'50 strains'!D138,'50 strains'!D159,'50 strains'!D180,'50 strains'!D201,'50 strains'!D222) -> 2.9256946e-17 | AD10: =STDEV('50 strains'!E33,'50 strains'!E54,'50 strains'!E75,'50 strains'!E96,'50 strains'!E117,'50 strains'!E138,'50 strains'!E159,'50 strains'!E180,'50 strains'!E201,'50 strains'!E222) -> 0.0081177886 | AE10: =STDEV('50 strains'!F33,'50 strains'!F54,'50 strains'!F75,'50 strains'!F96,'50 strains'!F117,'50 strains'!F138,'50 strains'!F159,'50 strains'!F180,'50 strains'!F201,'50 strains'!F222) -> 0.0063548476
A11: 10 | B11: 0.11090909 | C11: 0.1 | D11: 0.1 | E11: 0.17 | F11: 0.18157895 | G11: 0 | H11: 0 | I11: 0 | J11: 0 | K11: 0 | L11: =AVERAGE('15 strains'!B34,'15 strains'!B76,'15 strains'!B97,'15 strains'!B118,'15 strains'!B139,'15 strains'!B160,'15 strains'!B181,'15 strains'!B202,'15 strains'!B223) -> 0.10740741 | M11: =AVERAGE('15 strains'!C34,'15 strains'!C76,'15 strains'!C97,'15 strains'!C118,'15 strains'!C139,'15 strains'!C160,'15 strains'!C181,'15 strains'!C202,'15 strains'!C223) -> 0.1 | N11: =AVERAGE('15 strains'!D34,'15 strains'!D76,'15 strains'!D97,'15 strains'!D118,'15 strains'!D139,'15 strains'!D160,'15 strains'!D181,'15 strains'!D202,'15 strains'!D223) -> 0.1 | O11: =AVERAGE('15 strains'!E34,'15 strains'!E76,'15 strains'!E97,'15 strains'!E118,'15 strains'!E139,'15 strains'!E160,'15 strains'!E181,'15 strains'!E202,'15 strains'!E223) -> 0.16148148 | P11: =AVERAGE('15 strains'!F34,'15 strains'!F76,'15 strains'!F97,'15 strains'!F118,'15 strains'!F139,'15 strains'!F160,'15 strains'!F181,'15 strains'!F202,'15 strains'!F223) -> 0.17703704 | Q11: =STDEV('15 strains'!B34,'15 strains'!B76,'15 strains'!B97,'15 strains'!B118,'15 strains'!B139,'15 strains'!B160,'15 strains'!B181,'15 strains'!B202,'15 strains'!B223) -> 0.022959976 | R11: =STDEV('15 strains'!C34,'15 strains'!C76,'15 strains'!C97,'15 strains'!C118,'15 strains'!C139,'15 strains'!C160,'15 strains'!C181,'15 strains'!C202,'15 strains'!C223) -> 1.4719617e-17 | S11: =STDEV('15 strains'!D34,'15 strains'!D76,'15 strains'!D97,'15 strains'!D118,'15 strains'!D139,'15 strains'!D160,'15 strains'!D181,'15 strains'!D202,'15 strains'!D223) -> 1.4719617e-17 | T11: =STDEV('15 strains'!E34,'15 strains'!E76,'15 strains'!E97,'15 strains'!E118,'15 strains'!E139,'15 strains'!E160,'15 strains'!E181,'15 strains'!E202,'15 strains'!E223) -> 0.018189673 | U11: =STDEV('15 strains'!F34,'15 strains'!F76,'15 strains'!F97,'15 strains'!F118,'15 strains'!F139,'15 strains'!F160,'15 strains'!F181,'15 strains'!F202,'15 strains'!F223) -> 0.014572086 | V11: =AVERAGE('50 strains'!B34,'50 strains'!B55,'50 strains'!B76,'50 strains'!B97,'50 strains'!B118,'50 strains'!B139,'50 strains'!B160,'50 strains'!B181,'50 strains'!B202,'50 strains'!B223) -> 0.1084 | W11: =AVERAGE('50 strains'!C34,'50 strains'!C55,'50 strains'!C76,'50 strains'!C97,'50 strains'!C118,'50 strains'!C139,'50 strains'!C160,'50 strains'!C181,'50 strains'!C202,'50 strains'!C223) -> 0.1 | X11: =AVERAGE('50 strains'!D34,'50 strains'!D55,'50 strains'!D76,'50 strains'!D97,'50 strains'!D118,'50 strains'!D139,'50 strains'!D160,'50 strains'!D181,'50 strains'!D202,'50 strains'!D223) -> 0.1 | Y11: =AVERAGE('50 strains'!E34,'50 strains'!E55,'50 strains'!E76,'50 strains'!E97,'50 strains'!E118,'50 strains'!E139,'50 strains'!E160,'50 strains'!E181,'50 strains'!E202,'50 strains'!E223) -> 0.1638 | Z11: =AVERAGE('50 strains'!F34,'50 strains'!F55,'50 strains'!F76,'50 strains'!F97,'50 strains'!F118,'50 strains'!F139,'50 strains'!F160,'50 strains'!F181,'50 strains'!F202,'50 strains'!F223) -> 0.1862 | AA11: =STDEV('50 strains'!B34,'50 strains'!B55,'50 strains'!B76,'50 strains'!B97,'50 strains'!B118,'50 strains'!B139,'50 strains'!B160,'50 strains'!B181,'50 strains'!B202,'50 strains'!B223) -> 0.0082083968 | AB11: =STDEV('50 strains'!C34,'50 strains'!C55,'50 strains'!C76,'50 strains'!C97,'50 strains'!C118,'50 strains'!C139,'50 strains'!C160,'50 strains'!C181,'50 strains'!C202,'50 strains'!C223) -> 1.4628473e-17 | AC11: =STDEV('50 strains'!D34,'50 strains'!D55,'50 strains'!D76,'50 strains'!D97,'50 strains'!D118,'50 strains'!D139,'50 strains'!D160,'50 strains'!D181,'50 strains'!D202,'50 strains'!D223) -> 1.4628473e-17 | AD11: =STDEV('50 strains'!E34,'50 strains'!E55,'50 strains'!E76,'50 strains'!E97,'50 strains'!E118,'50 strains'!E139,'50 strains'!E160,'50 strains'!E181,'50 strains'!E202,'50 strains'!E223) -> 0.0064256431 | AE11: =STDEV('50 strains'!F34,'50 strains'!F55,'50 strains'!F76,'50 strains'!F97,'50 strains'!F118,'50 strains'!F139,'50 strains'!F160,'50 strains'!F181,'50 strains'!F202,'50 strains'!F223) -> 0.0070836274
A12: 11 | B12: 0.10413223 | C12: 0.18181818 | D12: 0.16515152 | E12: 0.18181818 | F12: 0.19059011 | G12: 0 | H12: 0 | I12: 0 | J12: 0 | K12: 0 | L12: =AVERAGE('15 strains'!B35,'15 strains'!B77,'15 strains'!B98,'15 strains'!B119,'15 strains'!B140,'15 strains'!B161,'15 strains'!B182,'15 strains'!B203,'15 strains'!B224) -> 0.1003367 | M12: =AVERAGE('15 strains'!C35,'15 strains'!C77,'15 strains'!C98,'15 strains'!C119,'15 strains'!C140,'15 strains'!C161,'15 strains'!C182,'15 strains'!C203,'15 strains'!C224) -> 0.18114478 | N12: =AVERAGE('15 strains'!D35,'15 strains'!D77,'15 strains'!D98,'15 strains'!D119,'15 strains'!D140,'15 strains'!D161,'15 strains'!D182,'15 strains'!D203,'15 strains'!D224) -> 0.16430976 | O12: =AVERAGE('15 strains'!E35,'15 strains'!E77,'15 strains'!E98,'15 strains'!E119,'15 strains'!E140,'15 strains'!E161,'15 strains'!E182,'15 strains'!E203,'15 strains'!E224) -> 0.17845118 | P12: =AVERAGE('15 strains'!F35,'15 strains'!F77,'15 strains'!F98,'15 strains'!F119,'15 strains'!F140,'15 strains'!F161,'15 strains'!F182,'15 strains'!F203,'15 strains'!F224) -> 0.18249158 | Q12: =STDEV('15 strains'!B35,'15 strains'!B77,'15 strains'!B98,'15 strains'!B119,'15 strains'!B140,'15 strains'!B161,'15 strains'!B182,'15 strains'!B203,'15 strains'!B224) -> 0.022290986 | R12: =STDEV('15 strains'!C35,'15 strains'!C77,'15 strains'!C98,'15 strains'!C119,'15 strains'!C140,'15 strains'!C161,'15 strains'!C182,'15 strains'!C203,'15 strains'!C224) -> 0.002020202 | S12: =STDEV('15 strains'!D35,'15 strains'!D77,'15 strains'!D98,'15 strains'!D119,'15 strains'!D140,'15 strains'!D161,'15 strains'!D182,'15 strains'!D203,'15 strains'!D224) -> 0.010689904 | T12: =STDEV('15 strains'!E35,'15 strains'!E77,'15 strains'!E98,'15 strains'!E119,'15 strains'!E140,'15 strains'!E161,'15 strains'!E182,'15 strains'!E203,'15 strains'!E224) -> 0.0068508384 | U12: =STDEV('15 strains'!F35,'15 strains'!F77,'15 strains'!F98,'15 strains'!F119,'15 strains'!F140,'15 strains'!F161,'15 strains'!F182,'15 strains'!F203,'15 strains'!F224) -> 0.015285602 | V12: =AVERAGE('50 strains'!B35,'50 strains'!B56,'50 strains'!B77,'50 strains'!B98,'50 strains'!B119,'50 strains'!B140,'50 strains'!B161,'50 strains'!B182,'50 strains'!B203,'50 strains'!B224) -> 0.10181818 | W12: =AVERAGE('50 strains'!C35,'50 strains'!C56,'50 strains'!C77,'50 strains'!C98,'50 strains'!C119,'50 strains'!C140,'50 strains'!C161,'50 strains'!C182,'50 strains'!C203,'50 strains'!C224) -> 0.18181818 | X12: =AVERAGE('50 strains'!D35,'50 strains'!D56,'50 strains'!D77,'50 strains'!D98,'50 strains'!D119,'50 strains'!D140,'50 strains'!D161,'50 strains'!D182,'50 strains'!D203,'50 strains'!D224) -> 0.16363636 | Y12: =AVERAGE('50 strains'!E35,'50 strains'!E56,'50 strains'!E77,'50 strains'!E98,'50 strains'!E119,'50 strains'!E140,'50 strains'!E161,'50 strains'!E182,'50 strains'!E203,'50 strains'!E224) -> 0.18018182 | Z12: =AVERAGE('50 strains'!F35,'50 strains'!F56,'50 strains'!F77,'50 strains'!F98,'50 strains'!F119,'50 strains'!F140,'50 strains'!F161,'50 strains'!F182,'50 strains'!F203,'50 strains'!F224) -> 0.19327273 | AA12: =STDEV('50 strains'!B35,'50 strains'!B56,'50 strains'!B77,'50 strains'!B98,'50 strains'!B119,'50 strains'!B140,'50 strains'!B161,'50 strains'!B182,'50 strains'!B203,'50 strains'!B224) -> 0.0080403025 | AB12: =STDEV('50 strains'!C35,'50 strains'!C56,'50 strains'!C77,'50 strains'!C98,'50 strains'!C119,'50 strains'!C140,'50 strains'!C161,'50 strains'!C182,'50 strains'!C203,'50 strains'!C224) -> 2.9256946e-17 | AC12: =STDEV('50 strains'!D35,'50 strains'!D56,'50 strains'!D77,'50 strains'!D98,'50 strains'!D119,'50 strains'!D140,'50 strains'!D161,'50 strains'!D182,'50 strains'!D203,'50 strains'!D224) -> 0.0079020635 | AD12: =STDEV('50 strains'!E35,'50 strains'!E56,'50 strains'!E77,'50 strains'!E98,'50 strains'!E119,'50 strains'!E140,'50 strains'!E161,'50 strains'!E182,'50 strains'!E203,'50 strains'!E224) -> 0.002770698 | AE12: =STDEV('50 strains'!F35,'50 strains'!F56,'50 strains'!F77,'50 strains'!F98,'50 strains'!F119,'50 strains'!F140,'50 strains'!F161,'50 strains'!F182,'50 strains'!F203,'50 strains'!F224) -> 0.0055579426
A13: 12 | B13: 0.16363636 | C13: 0.16666667 | D13: 0.16666667 | E13: 0.21319444 | F13: 0.19736842 | G13: 0 | H13: 0 | I13: 0 | J13: 0 | K13: 0 | L13: =AVERAGE('15 strains'!B36,'15 strains'!B78,'15 strains'!B99,'15 strains'!B120,'15 strains'!B141,'15 strains'!B162,'15 strains'!B183,'15 strains'!B204,'15 strains'!B225) -> 0.16358025 | M13: =AVERAGE('15 strains'!C36,'15 strains'!C78,'15 strains'!C99,'15 strains'!C120,'15 strains'!C141,'15 strains'!C162,'15 strains'!C183,'15 strains'!C204,'15 strains'!C225) -> 0.16666667 | N13: =AVERAGE('15 strains'!D36,'15 strains'!D78,'15 strains'!D99,'15 strains'!D120,'15 strains'!D141,'15 strains'!D162,'15 strains'!D183,'15 strains'!D204,'15 strains'!D225) -> 0.16234568 | O13: =AVERAGE('15 strains'!E36,'15 strains'!E78,'15 strains'!E99,'15 strains'!E120,'15 strains'!E141,'15 strains'!E162,'15 strains'!E183,'15 strains'!E204,'15 strains'!E225) -> 0.20555556 | P13: =AVERAGE('15 strains'!F36,'15 strains'!F78,'15 strains'!F99,'15 strains'!F120,'15 strains'!F141,'15 strains'!F162,'15 strains'!F183,'15 strains'!F204,'15 strains'!F225) -> 0.19506173 | Q13: =STDEV('15 strains'!B36,'15 strains'!B78,'15 strains'!B99,'15 strains'!B120,'15 strains'!B141,'15 strains'!B162,'15 strains'!B183,'15 strains'!B204,'15 strains'!B225) -> 0.022241504 | R13: =STDEV('15 strains'!C36,'15 strains'!C78,'15 strains'!C99,'15 strains'!C120,'15 strains'!C141,'15 strains'!C162,'15 strains'!C183,'15 strains'!C204,'15 strains'!C225) -> 0 | S13: =STDEV('15 strains'!D36,'15 strains'!D78,'15 strains'!D99,'15 strains'!D120,'15 strains'!D141,'15 strains'!D162,'15 strains'!D183,'15 strains'!D204,'15 strains'!D225) -> 0.0077468521 | T13: =STDEV('15 strains'!E36,'15 strains'!E78,'15 strains'!E99,'15 strains'!E120,'15 strains'!E141,'15 strains'!E162,'15 strains'!E183,'15 strains'!E204,'15 strains'!E225) -> 0.013888889 | U13: =STDEV('15 strains'!F36,'15 strains'!F78,'15 strains'!F99,'15 strains'!F120,'15 strains'!F141,'15 strains'!F162,'15 strains'!F183,'15 strains'!F204,'15 strains'!F225) -> 0.0097990789 | V13: =AVERAGE('50 strains'!B36,'50 strains'!B57,'50 strains'!B78,'50 strains'!B99,'50 strains'!B120,'50 strains'!B141,'50 strains'!B162,'50 strains'!B183,'50 strains'!B204,'50 strains'!B225) -> 0.16116667 | W13: =AVERAGE('50 strains'!C36,'50 strains'!C57,'50 strains'!C78,'50 strains'!C99,'50 strains'!C120,'50 strains'!C141,'50 strains'!C162,'50 strains'!C183,'50 strains'!C204,'50 strains'!C225) -> 0.16666667 | X13: =AVERAGE('50 strains'!D36,'50 strains'!D57,'50 strains'!D78,'50 strains'!D99,'50 strains'!D120,'50 strains'!D141,'50 strains'!D162,'50 strains'!D183,'50 strains'!D204,'50 strains'!D225) -> 0.16433333 | Y13: =AVERAGE('50 strains'!E36,'50 strains'!E57,'50 strains'!E78,'50 strains'!E99,'50 strains'!E120,'50 strains'!E141,'50 strains'!E162,'50 strains'!E183,'50 strains'!E204,'50 strains'!E225) -> 0.2095 | Z13: =AVERAGE('50 strains'!F36,'50 strains'!F57,'50 strains'!F78,'50 strains'!F99,'50 strains'!F120,'50 strains'!F141,'50 strains'!F162,'50 strains'!F183,'50 strains'!F204,'50 strains'!F225) -> 0.1985 | AA13: =STDEV('50 strains'!B36,'50 strains'!B57,'50 strains'!B78,'50 strains'!B99,'50 strains'!B120,'50 strains'!B141,'50 strains'!B162,'50 strains'!B183,'50 strains'!B204,'50 strains'!B225) -> 0.0071167512 | AB13: =STDEV('50 strains'!C36,'50 strains'!C57,'50 strains'!C78,'50 strains'!C99,'50 strains'!C120,'50 strains'!C141,'50 strains'!C162,'50 strains'!C183,'50 strains'!C204,'50 strains'!C225) -> 0 | AC13: =STDEV('50 strains'!D36,'50 strains'!D57,'50 strains'!D78,'50 strains'!D99,'50 strains'!D120,'50 strains'!D141,'50 strains'!D162,'50 strains'!D183,'50 strains'!D204,'50 strains'!D225) -> 0.0046613727 | AD13: =STDEV('50 strains'!E36,'50 strains'!E57,'50 strains'!E78,'50 strains'!E99,'50 strains'!E120,'50 strains'!E141,'50 strains'!E162,'50 strains'!E183,'50 strains'!E204,'50 strains'!E225) -> 0.0053315969 | AE13: =STDEV('50 strains'!F36,'50 strains'!F57,'50 strains'!F78,'50 strains'!F99,'50 strains'!F120,'50 strains'!F141,'50 strains'!F162,'50 strains'!F183,'50 strains'!F204,'50 strains'!F225) -> 0.0039635687
... A21: 20 | B21: 0.25363636 | C21: 0.23954545 | D21: 0.25 | E21: 0.27541667 | F21: 0.22982456 | G21: 0 | H21: 0 | I21: 0 | J21: 0 | K21: 0 | L21: =AVERAGE('15 strains'!B44,'15 strains'!B86,'15 strains'!B107,'15 strains'!B128,'15 strains'!B149,'15 strains'!B170,'15 strains'!B191,'15 strains'!B212,'15 strains'!B233) -> 0.25222222 | M21: =AVERAGE('15 strains'!C44,'15 strains'!C86,'15 strains'!C107,'15 strains'!C128,'15 strains'!C149,'15 strains'!C170,'15 strains'!C191,'15 strains'!C212,'15 strains'!C233) -> 0.23777778 | N21: =AVERAGE('15 strains'!D44,'15 strains'!D86,'15 strains'!D107,'15 strains'!D128,'15 strains'!D149,'15 strains'!D170,'15 strains'!D191,'15 strains'!D212,'15 strains'!D233) -> 0.25 | O21: =AVERAGE('15 strains'!E44,'15 strains'!E86,'15 strains'!E107,'15 strains'!E128,'15 strains'!E149,'15 strains'!E170,'15 strains'!E191,'15 strains'!E212,'15 strains'!E233) -> 0.26888889 | P21: =AVERAGE('15 strains'!F44,'15 strains'!F86,'15 strains'!F107,'15 strains'!F128,'15 strains'!F149,'15 strains'!F170,'15 strains'!F191,'15 strains'!F212,'15 strains'!F233) -> 0.22592593 | Q21: =STDEV('15 strains'!B44,'15 strains'!B86,'15 strains'!B107,'15 strains'!B128,'15 strains'!B149,'15 strains'!B170,'15 strains'!B191,'15 strains'!B212,'15 strains'!B233) -> 0.020344259 | R21: =STDEV('15 strains'!C44,'15 strains'!C86,'15 strains'!C107,'15 strains'!C128,'15 strains'!C149,'15 strains'!C170,'15 strains'!C191,'15 strains'!C212,'15 strains'!C233) -> 0.0062360956 | S21: =STDEV('15 strains'!D44,'15 strains'!D86,'15 strains'!D107,'15 strains'!D128,'15 strains'!D149,'15 strains'!D170,'15 strains'!D191,'15 strains'!D212,'15 strains'!D233) -> 0 | T21: =STDEV('15 strains'!E44,'15 strains'!E86,'15 strains'!E107,'15 strains'!E128,'15 strains'!E149,'15 strains'!E170,'15 strains'!E191,'15 strains'!E212,'15 strains'!E233) -> 0.012583057 | U21: =STDEV('15 strains'!F44,'15 strains'!F86,'15 strains'!F107,'15 strains'!F128,'15 strains'!F149,'15 strains'!F170,'15 strains'!F191,'15 strains'!F212,'15 strains'!F233) -> 0.012335335 | V21: =AVERAGE('50 strains'!B44,'50 strains'!B65,'50 strains'!B86,'50 strains'!B107,'50 strains'!B128,'50 strains'!B149,'50 strains'!B170,'50 strains'!B191,'50 strains'!B212,'50 strains'!B233) -> 0.2511 | W21: =AVERAGE('50 strains'!C44,'50 strains'!C65,'50 strains'!C86,'50 strains'!C107,'50 strains'!C128,'50 strains'!C149,'50 strains'!C170,'50 strains'!C191,'50 strains'!C212,'50 strains'!C233) -> 0.2394 | X21: =AVERAGE('50 strains'!D44,'50 strains'!D65,'50 strains'!D86,'50 strains'!D107,'50 strains'!D128,'50 strains'!D149,'50 strains'!D170,'50 strains'!D191,'50 strains'!D212,'50 strains'!D233) -> 0.25 | Y21: =AVERAGE('50 strains'!E44,'50 strains'!E65,'50 strains'!E86,'50 strains'!E107,'50 strains'!E128,'50 strains'!E149,'50 strains'!E170,'50 strains'!E191,'50 strains'!E212,'50 strains'!E233) -> 0.271 | Z21: =AVERAGE('50 strains'!F44,'50 strains'!F65,'50 strains'!F86,'50 strains'!F107,'50 strains'!F128,'50 strains'!F149,'50 strains'!F170,'50 strains'!F191,'50 strains'!F212,'50 strains'!F233) -> 0.2335 | AA21: =STDEV('50 strains'!B44,'50 strains'!B65,'50 strains'!B86,'50 strains'!B107,'50 strains'!B128,'50 strains'!B149,'50 strains'!B170,'50 strains'!B191,'50 strains'!B212,'50 strains'!B233) -> 0.0059338951 | AB21: =STDEV('50 strains'!C44,'50 strains'!C65,'50 strains'!C86,'50 strains'!C107,'50 strains'!C128,'50 strains'!C149,'50 strains'!C170,'50 strains'!C191,'50 strains'!C212,'50 strains'!C233) -> 0.0021705094 | AC21: =STDEV('50 strains'!D44,'50 strains'!D65,'50 strains'!D86,'50 strains'!D107,'50 strains'!D128,'50 strains'!D149,'50 strains'!D170,'50 strains'!D191,'50 strains'!D212,'50 strains'!D233) -> 0 | AD21: =STDEV('50 strains'!E44,'50 strains'!E65,'50 strains'!E86,'50 strains'!E107,'50 strains'!E128,'50 strains'!E149,'50 strains'!E170,'50 strains'!E191,'50 strains'!E212,'50 strains'!E233) -> 0.0053541261 | AE21: =STDEV('50 strains'!F44,'50 strains'!F65,'50 strains'!F86,'50 strains'!F107,'50 strains'!F128,'50 strains'!F149,'50 strains'!F170,'50 strains'!F191,'50 strains'!F212,'50 strains'!F233) -> 0.0050607422

Sheet merged_details
A1: Sample | B1: Region | C1: Strains | D1: Type
A2: V1–V2-120 | B2: V1–V2 | C2: All 120 strains | D2: avg
A3: V1–V3-120 | B3: V1–V3 | C3: All 120 strains | D3: avg
A4: V4-120 | B4: V4 | C4: All 120 strains | D4: avg
A5: V3–V5-120 | B5: V3–V5 | C5: All 120 strains | D5: avg
A6: V6–V9-120 | B6: V6–V9 | C6: All 120 strains | D6: avg
A7: V1–V2-120-stdev | B7: V1–V2 | C7: All 120 strains | D7: stdev
A8: V1–V3-120-stdev | B8: V1–V3 | C8: All 120 strains | D8: stdev
A9: V4-120-stdev | B9: V4 | C9: All 120 strains | D9: stdev
A10: V3–V5-120-stdev | B10: V3–V5 | C10: All 120 strains | D10: stdev
A11: V6–V9-120-stdev | B11: V6–V9 | C11: All 120 strains | D11: stdev
A12: V1–V2-15 | B12: V1–V2 | C12: 15 strains | D12: avg
... A31: V6–V9-50-stdev | B31: V6–V9 | C31: 50 strains | D31: stdev

Sheet 15 strains
A1: mean | B1: V1-V2 | C1: V1-V3 | D1: V4 | E1: V3-V5 | F1: V6-V9 | H1: V1-V2 | I1: V1-V3 | J1: V4 | K1: V3-V5 | L1: V6-V9
B2: 0 | C2: 0 | D2: 0 | E2: 0 | F2: 0 | H2: 0 | I2: 0 | J2: 0 | K2: 0 | L2: 0
B3: 0 | C3: 0 | D3: 0 | E3: 0 | F3: 0 | H3: 0 | I3: 0 | J3: 0 | K3: 0 | L3: 0
B4: 0 | C4: 0 | D4: 0 | E4: 0 | F4: 0 | H4: 0 | I4: 0 | J4: 0 | K4: 0 | L4: 0
B5: 0 | C5: 0 | D5: 0 | E5: 0 | F5: 0 | H5: 0 | I5: 0 | J5: 0 | K5: 0 | L5: 0
B6: 0.0013333333 | C6: 0 | D6: 0 | E6: 0.012 | F6: 0.025333333 | H6: 0.0042163702 | I6: 0 | J6: 0 | K6: 0.017155786 | L6: 0.020318452
B7: 0.061111111 | C7: 0 | D7: 0 | E7: 0.072222222 | F7: 0.071111111 | H7: 0.018332398 | I7: 0 | J7: 0 | K7: 0.015930232 | L7: 0.019029974
B8: 0.1 | C8: 0 | D8: 0 | E8: 0.095238095 | F8: 0.068571429 | H8: 0.028127056 | I8: 0 | J8: 0 | K8: 0.02057378 | L8: 0.018941503
B9: 0.11083333 | C9: 0.125 | D9: 0.085833333 | E9: 0.12333333 | F9: 0.13166667 | H9: 0.018860272 | I9: 0 | J9: 0.014724843 | K9: 0.0052704628 | L9: 0.018341749
B10: 0.11407407 | C10: 0.11111111 | D10: 0.11111111 | E10: 0.16740741 | F10: 0.15777778 | H10: 0.02424284 | I10: 2.9256946e-17 | J10: 2.9256946e-17 | K10: 0.016077848 | L10: 0.018493811
B11: 0.10733333 | C11: 0.1 | D11: 0.1 | E11: 0.16266667 | F11: 0.17533333 | H11: 0.02164814 | I11: 1.4628473e-17 | J11: 1.4628473e-17 | K11: 0.017554149 | L11: 0.014757296
B12: 0.1 | C12: 0.18121212 | D12: 0.16484848 | E12: 0.17878788 | F12: 0.18181818 | H12: 0.021043098 | I12: 0.0019165319 | J12: 0.010221504 | K12: 0.0065462027 | L12: 0.014567884
B13: 0.16388889 | C13: 0.16666667 | D13: 0.16277778 | E13: 0.20666667 | F13: 0.19444444 | H13: 0.020992193 | I13: 2.9256946e-17 | J13: 0.0074305195 | K13: 0.013557782 | L13: 0.0094426287
... B21: 0.25333333 | C21: 0.238 | D21: 0.25 | E21: 0.269 | F21: 0.22533333 | H21: 0.019499921 | I21: 0.0059212945 | J21: 0 | K21: 0.011868622 | L21: 0.011779874
A25: rep1 | B25: 0 | C25: 0 | D25: 0 | E25: 0 | F25: 0
B26: 0 | C26: 0 | D26: 0 | E26: 0 | F26: 0
B27: 0 | C27: 0 | D27: 0 | E27: 0 | F27: 0
B28: 0 | C28: 0 | D28: 0 | E28: 0 | F28: 0
B29: 0 | C29: 0 | D29: 0 | E29: 0 | F29: 0.04
B30: 0.066666667 | C30: 0 | D30: 0 | E30: 0.077777778 | F30: 0.077777778
B31: 0.11428571 | C31: 0 | D31: 0 | E31: 0.12380952 | F31: 0.076190476
B32: 0.125 | C32: 0.125 | D32: 0.091666667 | E32: 0.125 | F32: 0.125
B33: 0.12592593 | C33: 0.11111111 | D33: 0.11111111 | E33: 0.18518519 | F33: 0.14814815
B34: 0.12666667 | C34: 0.1 | D34: 0.1 | E34: 0.18 | F34: 0.16666667
B35: 0.11515152 | C35: 0.18181818 | D35: 0.16969697 | E35: 0.18181818 | F35: 0.17575758
B36: 0.17777778 | C36: 0.16666667 | D36: 0.16666667 | E36: 0.21111111 | F36: 0.18333333
B37: 0.17948718 | C37: 0.15384615 | D37: 0.15384615 | E37: 0.20512821 | F37: 0.18461538
... B44: 0.26333333 | C44: 0.23 | D44: 0.25 | E44: 0.25666667 | F44: 0.22
A46: rep2 | B46: 0 | C46: 0 | D46: 0 | E46: 0 | F46: 0
B47: 0 | C47: 0 | D47: 0 | E47: 0 | F47: 0
B48: 0 | C48: 0 | D48: 0 | E48: 0 | F48: 0
B49: 0 | C49: 0 | D49: 0 | E49: 0 | F49: 0
B50: 0 | C50: 0 | D50: 0 | E50: 0.026666667 | F50: 0.013333333
B51: 0.088888889 | C51: 0 | D51: 0 | E51: 0.077777778 | F51: 0.066666667
B52: 0.11428571 | C52: 0 | D52: 0 | E52: 0.1047619 | F52: 0.066666667
B53: 0.10833333 | C53: 0.125 | D53: 0.1 | E53: 0.125 | F53: 0.13333333
B54: 0.11851852 | C54: 0.11111111 | D54: 0.11111111 | E54: 0.17777778 | F54: 0.15555556
B55: 0.10666667 | C55: 0.1 | D55: 0.1 | E55: 0.17333333 | F55: 0.16
B56: 0.096969697 | C56: 0.18181818 | D56: 0.16969697 | E56: 0.18181818 | F56: 0.17575758
B57: 0.16666667 | C57: 0.16666667 | D57: 0.16666667 | E57: 0.21666667 | F57: 0.18888889
...

Sheet 50 strains
A1: mean | B1: V1-V2 | C1: V1-V3 | D1: V4 | E1: V3-V5 | F1: V6-V9 | H1: V1-V2 | I1: V1-V3 | J1: V4 | K1: V3-V5 | L1: V6-V9
B2: 0 | C2: 0 | D2: 0 | E2: 0 | F2: 0 | H2: 0 | I2: 0 | J2: 0 | K2: 0 | L2: 0
B3: 0 | C3: 0 | D3: 0 | E3: 0 | F3: 0 | H3: 0 | I3: 0 | J3: 0 | K3: 0 | L3: 0
B4: 0 | C4: 0 | D4: 0 | E4: 0 | F4: 0 | H4: 0 | I4: 0 | J4: 0 | K4: 0 | L4: 0
B5: 0 | C5: 0 | D5: 0 | E5: 0 | F5: 0 | H5: 0 | I5: 0 | J5: 0 | K5: 0 | L5: 0
B6: 0.002 | C6: 0 | D6: 0 | E6: 0.0132 | F6: 0.028 | H6: 0.0021081851 | I6: 0 | J6: 0 | K6: 0.0081758452 | L6: 0.012220202
B7: 0.068333333 | C7: 0 | D7: 0 | E7: 0.071333333 | F7: 0.078333333 | H7: 0.011138854 | I7: 0 | J7: 0 | K7: 0.0116746 | L7: 0.012692955
B8: 0.099428571 | C8: 0 | D8: 0 | E8: 0.10342857 | F8: 0.072285714 | H8: 0.012106856 | I8: 0 | J8: 0 | K8: 0.015226186 | L8: 0.012200145
B9: 0.1185 | C9: 0.125 | D9: 0.088 | E9: 0.125 | F9: 0.1295 | H9: 0.005027701 | I9: 0 | J9: 0.00831665 | K9: 0 | L9: 0.012791056
B10: 0.11888889 | C10: 0.11111111 | D10: 0.11111111 | E10: 0.166 | F10: 0.176 | H10: 0.0081312957 | I10: 2.9256946e-17 | J10: 2.9256946e-17 | K10: 0.0081177886 | L10: 0.0063548476
B11: 0.1084 | C11: 0.1 | D11: 0.1 | E11: 0.1638 | F11: 0.1862 | H11: 0.0082083968 | I11: 1.4628473e-17 | J11: 1.4628473e-17 | K11: 0.0064256431 | L11: 0.0070836274
B12: 0.10181818 | C12: 0.18181818 | D12: 0.16363636 | E12: 0.18018182 | F12: 0.19327273 | H12: 0.0080403025 | I12: 2.9256946e-17 | J12: 0.0079020635 | K12: 0.002770698 | L12: 0.0055579426
B13: 0.16116667 | C13: 0.16666667 | D13: 0.16433333 | E13: 0.2095 | F13: 0.1985 | H13: 0.0071167512 | I13: 2.9256946e-17 | J13: 0.0046613727 | K13: 0.0053315969 | L13: 0.0039635687
... B21: 0.2511 | C21: 0.2394 | D21: 0.25 | E21: 0.271 | F21: 0.2335 | H21: 0.0059338951 | I21: 0.0021705094 | J21: 0 | K21: 0.0053541261 | L21: 0.0050607422
A25: rep1 | B25: 0 | C25: 0 | D25: 0 | E25: 0 | F25: 0
B26: 0 | C26: 0 | D26: 0 | E26: 0 | F26: 0
B27: 0 | C27: 0 | D27: 0 | E27: 0 | F27: 0
B28: 0 | C28: 0 | D28: 0 | E28: 0 | F28: 0
B29: 0 | C29: 0 | D29: 0 | E29: 0.014 | F29: 0.012
B30: 0.083333333 | C30: 0 | D30: 0 | E30: 0.07 | F30: 0.063333333
B31: 0.1 | C31: 0 | D31: 0 | E31: 0.10857143 | F31: 0.057142857
B32: 0.1175 | C32: 0.125 | D32: 0.095 | E32: 0.125 | F32: 0.12
B33: 0.11555556 | C33: 0.11111111 | D33: 0.11111111 | E33: 0.16444444 | F33: 0.17333333
B34: 0.104 | C34: 0.1 | D34: 0.1 | E34: 0.164 | F34: 0.184
B35: 0.098181818 | C35: 0.18181818 | D35: 0.17454545 | E35: 0.18181818 | F35: 0.19272727
B36: 0.15166667 | C36: 0.16666667 | D36: 0.16666667 | E36: 0.21 | F36: 0.19833333
B37: 0.15076923 | C37: 0.15384615 | D37: 0.15384615 | E37: 0.2 | F37: 0.20461538
... B44: 0.245 | C44: 0.241 | D44: 0.25 | E44: 0.276 | F44: 0.235
A46: rep2 | B46: 0 | C46: 0 | D46: 0 | E46: 0 | F46: 0
B47: 0 | C47: 0 | D47: 0 | E47: 0 | F47: 0
B48: 0 | C48: 0 | D48: 0 | E48: 0 | F48: 0
B49: 0 | C49: 0 | D49: 0 | E49: 0 | F49: 0
B50: 0.004 | C50: 0 | D50: 0 | E50: 0.014 | F50: 0.04
B51: 0.08 | C51: 0 | D51: 0 | E51: 0.056666667 | F51: 0.083333333
B52: 0.11428571 | C52: 0 | D52: 0 | E52: 0.085714286 | F52: 0.08
B53: 0.12 | C53: 0.125 | D53: 0.0925 | E53: 0.125 | F53: 0.1375
